























Hello world email body


Hello world email body


Hello world email body


Hello world email body








Hello world email body










Hello world email body


Hello world email body


Hello world email body


Hello world email body


Hello world email body
















Traceback (most recent call last):
  File "/home/pi/Desktop/message.py", line 23, in <module>
    conn = psycopg2.connect(database="performance", user='pi', password='Sox2017!', host='192.168.0.235', port= '5432')
  File "/usr/local/lib/python2.7/dist-packages/psycopg2/__init__.py", line 127, in connect
    conn = _connect(dsn, connection_factory=connection_factory, **kwasync)
psycopg2.OperationalError: could not connect to server: Network is unreachable
	Is the server running on host "192.168.0.235" and accepting
	TCP/IP connections on port 5432?



Traceback (most recent call last):
  File "/home/pi/Desktop/message.py", line 23, in <module>
    conn = psycopg2.connect(database="performance", user='pi', password='Sox2017!', host='192.168.0.235', port= '5432')
  File "/usr/local/lib/python2.7/dist-packages/psycopg2/__init__.py", line 127, in connect
    conn = _connect(dsn, connection_factory=connection_factory, **kwasync)
psycopg2.OperationalError: could not connect to server: Network is unreachable
	Is the server running on host "192.168.0.235" and accepting
	TCP/IP connections on port 5432?



Traceback (most recent call last):
  File "/home/pi/Desktop/message.py", line 23, in <module>
    conn = psycopg2.connect(database="performance", user='pi', password='Sox2017!', host='192.168.0.235', port= '5432')
  File "/usr/local/lib/python2.7/dist-packages/psycopg2/__init__.py", line 127, in connect
    conn = _connect(dsn, connection_factory=connection_factory, **kwasync)
psycopg2.OperationalError: could not connect to server: Network is unreachable
	Is the server running on host "192.168.0.235" and accepting
	TCP/IP connections on port 5432?



Traceback (most recent call last):
  File "/home/pi/Desktop/message.py", line 23, in <module>
    conn = psycopg2.connect(database="performance", user='pi', password='Sox2017!', host='192.168.0.235', port= '5432')
  File "/usr/local/lib/python2.7/dist-packages/psycopg2/__init__.py", line 127, in connect
    conn = _connect(dsn, connection_factory=connection_factory, **kwasync)
psycopg2.OperationalError: could not connect to server: Network is unreachable
	Is the server running on host "192.168.0.235" and accepting
	TCP/IP connections on port 5432?



Traceback (most recent call last):
  File "/home/pi/Desktop/message.py", line 23, in <module>
    conn = psycopg2.connect(database="performance", user='pi', password='Sox2017!', host='192.168.0.235', port= '5432')
  File "/usr/local/lib/python2.7/dist-packages/psycopg2/__init__.py", line 127, in connect
    conn = _connect(dsn, connection_factory=connection_factory, **kwasync)
psycopg2.OperationalError: could not connect to server: Network is unreachable
	Is the server running on host "192.168.0.235" and accepting
	TCP/IP connections on port 5432?



Traceback (most recent call last):
  File "/home/pi/Desktop/message.py", line 23, in <module>
    conn = psycopg2.connect(database="performance", user='pi', password='Sox2017!', host='192.168.0.235', port= '5432')
  File "/usr/local/lib/python2.7/dist-packages/psycopg2/__init__.py", line 127, in connect
    conn = _connect(dsn, connection_factory=connection_factory, **kwasync)
psycopg2.OperationalError: could not connect to server: Network is unreachable
	Is the server running on host "192.168.0.235" and accepting
	TCP/IP connections on port 5432?



Traceback (most recent call last):
  File "/home/pi/Desktop/message.py", line 23, in <module>
    conn = psycopg2.connect(database="performance", user='pi', password='Sox2017!', host='192.168.0.235', port= '5432')
  File "/usr/local/lib/python2.7/dist-packages/psycopg2/__init__.py", line 127, in connect
    conn = _connect(dsn, connection_factory=connection_factory, **kwasync)
psycopg2.OperationalError: could not connect to server: Network is unreachable
	Is the server running on host "192.168.0.235" and accepting
	TCP/IP connections on port 5432?



Traceback (most recent call last):
  File "/home/pi/Desktop/message.py", line 23, in <module>
    conn = psycopg2.connect(database="performance", user='pi', password='Sox2017!', host='192.168.0.235', port= '5432')
  File "/usr/local/lib/python2.7/dist-packages/psycopg2/__init__.py", line 127, in connect
    conn = _connect(dsn, connection_factory=connection_factory, **kwasync)
psycopg2.OperationalError: could not connect to server: Network is unreachable
	Is the server running on host "192.168.0.235" and accepting
	TCP/IP connections on port 5432?



Traceback (most recent call last):
  File "/home/pi/Desktop/message.py", line 23, in <module>
    conn = psycopg2.connect(database="performance", user='pi', password='Sox2017!', host='192.168.0.235', port= '5432')
  File "/usr/local/lib/python2.7/dist-packages/psycopg2/__init__.py", line 127, in connect
    conn = _connect(dsn, connection_factory=connection_factory, **kwasync)
psycopg2.OperationalError: could not connect to server: Network is unreachable
	Is the server running on host "192.168.0.235" and accepting
	TCP/IP connections on port 5432?



Traceback (most recent call last):
  File "/home/pi/Desktop/message.py", line 23, in <module>
    conn = psycopg2.connect(database="performance", user='pi', password='Sox2017!', host='192.168.0.235', port= '5432')
  File "/usr/local/lib/python2.7/dist-packages/psycopg2/__init__.py", line 127, in connect
    conn = _connect(dsn, connection_factory=connection_factory, **kwasync)
psycopg2.OperationalError: could not connect to server: Network is unreachable
	Is the server running on host "192.168.0.235" and accepting
	TCP/IP connections on port 5432?



Traceback (most recent call last):
  File "/home/pi/Desktop/message.py", line 23, in <module>
    conn = psycopg2.connect(database="performance", user='pi', password='Sox2017!', host='192.168.0.235', port= '5432')
  File "/usr/local/lib/python2.7/dist-packages/psycopg2/__init__.py", line 127, in connect
    conn = _connect(dsn, connection_factory=connection_factory, **kwasync)
psycopg2.OperationalError: could not connect to server: Network is unreachable
	Is the server running on host "192.168.0.235" and accepting
	TCP/IP connections on port 5432?



Traceback (most recent call last):
  File "/home/pi/Desktop/message.py", line 23, in <module>
    conn = psycopg2.connect(database="performance", user='pi', password='Sox2017!', host='192.168.0.235', port= '5432')
  File "/usr/local/lib/python2.7/dist-packages/psycopg2/__init__.py", line 127, in connect
    conn = _connect(dsn, connection_factory=connection_factory, **kwasync)
psycopg2.OperationalError: could not connect to server: Network is unreachable
	Is the server running on host "192.168.0.235" and accepting
	TCP/IP connections on port 5432?



Traceback (most recent call last):
  File "/home/pi/Desktop/message.py", line 23, in <module>
    conn = psycopg2.connect(database="performance", user='pi', password='Sox2017!', host='192.168.0.235', port= '5432')
  File "/usr/local/lib/python2.7/dist-packages/psycopg2/__init__.py", line 127, in connect
    conn = _connect(dsn, connection_factory=connection_factory, **kwasync)
psycopg2.OperationalError: could not connect to server: Network is unreachable
	Is the server running on host "192.168.0.235" and accepting
	TCP/IP connections on port 5432?



Traceback (most recent call last):
  File "/home/pi/Desktop/message.py", line 23, in <module>
    conn = psycopg2.connect(database="performance", user='pi', password='Sox2017!', host='192.168.0.235', port= '5432')
  File "/usr/local/lib/python2.7/dist-packages/psycopg2/__init__.py", line 127, in connect
    conn = _connect(dsn, connection_factory=connection_factory, **kwasync)
psycopg2.OperationalError: could not connect to server: Network is unreachable
	Is the server running on host "192.168.0.235" and accepting
	TCP/IP connections on port 5432?



Traceback (most recent call last):
  File "/home/pi/Desktop/message.py", line 23, in <module>
    conn = psycopg2.connect(database="performance", user='pi', password='Sox2017!', host='192.168.0.235', port= '5432')
  File "/usr/local/lib/python2.7/dist-packages/psycopg2/__init__.py", line 127, in connect
    conn = _connect(dsn, connection_factory=connection_factory, **kwasync)
psycopg2.OperationalError: could not connect to server: Network is unreachable
	Is the server running on host "192.168.0.235" and accepting
	TCP/IP connections on port 5432?



Traceback (most recent call last):
  File "/home/pi/Desktop/message.py", line 23, in <module>
    conn = psycopg2.connect(database="performance", user='pi', password='Sox2017!', host='192.168.0.235', port= '5432')
  File "/usr/local/lib/python2.7/dist-packages/psycopg2/__init__.py", line 127, in connect
    conn = _connect(dsn, connection_factory=connection_factory, **kwasync)
psycopg2.OperationalError: could not connect to server: Network is unreachable
	Is the server running on host "192.168.0.235" and accepting
	TCP/IP connections on port 5432?



Traceback (most recent call last):
  File "/home/pi/Desktop/message.py", line 23, in <module>
    conn = psycopg2.connect(database="performance", user='pi', password='Sox2017!', host='192.168.0.235', port= '5432')
  File "/usr/local/lib/python2.7/dist-packages/psycopg2/__init__.py", line 127, in connect
    conn = _connect(dsn, connection_factory=connection_factory, **kwasync)
psycopg2.OperationalError: could not connect to server: Network is unreachable
	Is the server running on host "192.168.0.235" and accepting
	TCP/IP connections on port 5432?



Traceback (most recent call last):
  File "/home/pi/Desktop/message.py", line 23, in <module>
    conn = psycopg2.connect(database="performance", user='pi', password='Sox2017!', host='192.168.0.235', port= '5432')
  File "/usr/local/lib/python2.7/dist-packages/psycopg2/__init__.py", line 127, in connect
    conn = _connect(dsn, connection_factory=connection_factory, **kwasync)
psycopg2.OperationalError: could not connect to server: Network is unreachable
	Is the server running on host "192.168.0.235" and accepting
	TCP/IP connections on port 5432?



Traceback (most recent call last):
  File "/home/pi/Desktop/message.py", line 23, in <module>
    conn = psycopg2.connect(database="performance", user='pi', password='Sox2017!', host='192.168.0.235', port= '5432')
  File "/usr/local/lib/python2.7/dist-packages/psycopg2/__init__.py", line 127, in connect
    conn = _connect(dsn, connection_factory=connection_factory, **kwasync)
psycopg2.OperationalError: could not connect to server: Network is unreachable
	Is the server running on host "192.168.0.235" and accepting
	TCP/IP connections on port 5432?



Traceback (most recent call last):
  File "/home/pi/Desktop/message.py", line 23, in <module>
    conn = psycopg2.connect(database="performance", user='pi', password='Sox2017!', host='192.168.0.235', port= '5432')
  File "/usr/local/lib/python2.7/dist-packages/psycopg2/__init__.py", line 127, in connect
    conn = _connect(dsn, connection_factory=connection_factory, **kwasync)
psycopg2.OperationalError: could not connect to server: Network is unreachable
	Is the server running on host "192.168.0.235" and accepting
	TCP/IP connections on port 5432?



Traceback (most recent call last):
  File "/home/pi/Desktop/message.py", line 23, in <module>
    conn = psycopg2.connect(database="performance", user='pi', password='Sox2017!', host='192.168.0.235', port= '5432')
  File "/usr/local/lib/python2.7/dist-packages/psycopg2/__init__.py", line 127, in connect
    conn = _connect(dsn, connection_factory=connection_factory, **kwasync)
psycopg2.OperationalError: could not connect to server: Network is unreachable
	Is the server running on host "192.168.0.235" and accepting
	TCP/IP connections on port 5432?



Traceback (most recent call last):
  File "/home/pi/Desktop/message.py", line 23, in <module>
    conn = psycopg2.connect(database="performance", user='pi', password='Sox2017!', host='192.168.0.235', port= '5432')
  File "/usr/local/lib/python2.7/dist-packages/psycopg2/__init__.py", line 127, in connect
    conn = _connect(dsn, connection_factory=connection_factory, **kwasync)
psycopg2.OperationalError: could not connect to server: Network is unreachable
	Is the server running on host "192.168.0.235" and accepting
	TCP/IP connections on port 5432?



Traceback (most recent call last):
  File "/home/pi/Desktop/message.py", line 23, in <module>
    conn = psycopg2.connect(database="performance", user='pi', password='Sox2017!', host='192.168.0.235', port= '5432')
  File "/usr/local/lib/python2.7/dist-packages/psycopg2/__init__.py", line 127, in connect
    conn = _connect(dsn, connection_factory=connection_factory, **kwasync)
psycopg2.OperationalError: could not connect to server: Network is unreachable
	Is the server running on host "192.168.0.235" and accepting
	TCP/IP connections on port 5432?



Traceback (most recent call last):
  File "/home/pi/Desktop/message.py", line 23, in <module>
    conn = psycopg2.connect(database="performance", user='pi', password='Sox2017!', host='192.168.0.235', port= '5432')
  File "/usr/local/lib/python2.7/dist-packages/psycopg2/__init__.py", line 127, in connect
    conn = _connect(dsn, connection_factory=connection_factory, **kwasync)
psycopg2.OperationalError: could not connect to server: Network is unreachable
	Is the server running on host "192.168.0.235" and accepting
	TCP/IP connections on port 5432?



Traceback (most recent call last):
  File "/home/pi/Desktop/message.py", line 23, in <module>
    conn = psycopg2.connect(database="performance", user='pi', password='Sox2017!', host='192.168.0.235', port= '5432')
  File "/usr/local/lib/python2.7/dist-packages/psycopg2/__init__.py", line 127, in connect
    conn = _connect(dsn, connection_factory=connection_factory, **kwasync)
psycopg2.OperationalError: could not connect to server: Network is unreachable
	Is the server running on host "192.168.0.235" and accepting
	TCP/IP connections on port 5432?



Traceback (most recent call last):
  File "/home/pi/Desktop/message.py", line 23, in <module>
    conn = psycopg2.connect(database="performance", user='pi', password='Sox2017!', host='192.168.0.235', port= '5432')
  File "/usr/local/lib/python2.7/dist-packages/psycopg2/__init__.py", line 127, in connect
    conn = _connect(dsn, connection_factory=connection_factory, **kwasync)
psycopg2.OperationalError: could not connect to server: Network is unreachable
	Is the server running on host "192.168.0.235" and accepting
	TCP/IP connections on port 5432?



Traceback (most recent call last):
  File "/home/pi/Desktop/message.py", line 23, in <module>
    conn = psycopg2.connect(database="performance", user='pi', password='Sox2017!', host='192.168.0.235', port= '5432')
  File "/usr/local/lib/python2.7/dist-packages/psycopg2/__init__.py", line 127, in connect
    conn = _connect(dsn, connection_factory=connection_factory, **kwasync)
psycopg2.OperationalError: could not connect to server: Network is unreachable
	Is the server running on host "192.168.0.235" and accepting
	TCP/IP connections on port 5432?



Traceback (most recent call last):
  File "/home/pi/Desktop/message.py", line 23, in <module>
    conn = psycopg2.connect(database="performance", user='pi', password='Sox2017!', host='192.168.0.235', port= '5432')
  File "/usr/local/lib/python2.7/dist-packages/psycopg2/__init__.py", line 127, in connect
    conn = _connect(dsn, connection_factory=connection_factory, **kwasync)
psycopg2.OperationalError: could not connect to server: Network is unreachable
	Is the server running on host "192.168.0.235" and accepting
	TCP/IP connections on port 5432?



Traceback (most recent call last):
  File "/home/pi/Desktop/message.py", line 23, in <module>
    conn = psycopg2.connect(database="performance", user='pi', password='Sox2017!', host='192.168.0.235', port= '5432')
  File "/usr/local/lib/python2.7/dist-packages/psycopg2/__init__.py", line 127, in connect
    conn = _connect(dsn, connection_factory=connection_factory, **kwasync)
psycopg2.OperationalError: could not connect to server: Network is unreachable
	Is the server running on host "192.168.0.235" and accepting
	TCP/IP connections on port 5432?



Traceback (most recent call last):
  File "/home/pi/Desktop/message.py", line 23, in <module>
    conn = psycopg2.connect(database="performance", user='pi', password='Sox2017!', host='192.168.0.235', port= '5432')
  File "/usr/local/lib/python2.7/dist-packages/psycopg2/__init__.py", line 127, in connect
    conn = _connect(dsn, connection_factory=connection_factory, **kwasync)
psycopg2.OperationalError: could not connect to server: Network is unreachable
	Is the server running on host "192.168.0.235" and accepting
	TCP/IP connections on port 5432?



Traceback (most recent call last):
  File "/home/pi/Desktop/message.py", line 23, in <module>
    conn = psycopg2.connect(database="performance", user='pi', password='Sox2017!', host='192.168.0.235', port= '5432')
  File "/usr/local/lib/python2.7/dist-packages/psycopg2/__init__.py", line 127, in connect
    conn = _connect(dsn, connection_factory=connection_factory, **kwasync)
psycopg2.OperationalError: could not connect to server: Network is unreachable
	Is the server running on host "192.168.0.235" and accepting
	TCP/IP connections on port 5432?



Traceback (most recent call last):
  File "/home/pi/Desktop/message.py", line 23, in <module>
    conn = psycopg2.connect(database="performance", user='pi', password='Sox2017!', host='192.168.0.235', port= '5432')
  File "/usr/local/lib/python2.7/dist-packages/psycopg2/__init__.py", line 127, in connect
    conn = _connect(dsn, connection_factory=connection_factory, **kwasync)
psycopg2.OperationalError: could not connect to server: Network is unreachable
	Is the server running on host "192.168.0.235" and accepting
	TCP/IP connections on port 5432?



Traceback (most recent call last):
  File "/home/pi/Desktop/message.py", line 23, in <module>
    conn = psycopg2.connect(database="performance", user='pi', password='Sox2017!', host='192.168.0.235', port= '5432')
  File "/usr/local/lib/python2.7/dist-packages/psycopg2/__init__.py", line 127, in connect
    conn = _connect(dsn, connection_factory=connection_factory, **kwasync)
psycopg2.OperationalError: could not connect to server: Network is unreachable
	Is the server running on host "192.168.0.235" and accepting
	TCP/IP connections on port 5432?



Traceback (most recent call last):
  File "/home/pi/Desktop/message.py", line 23, in <module>
    conn = psycopg2.connect(database="performance", user='pi', password='Sox2017!', host='192.168.0.235', port= '5432')
  File "/usr/local/lib/python2.7/dist-packages/psycopg2/__init__.py", line 127, in connect
    conn = _connect(dsn, connection_factory=connection_factory, **kwasync)
psycopg2.OperationalError: could not connect to server: Network is unreachable
	Is the server running on host "192.168.0.235" and accepting
	TCP/IP connections on port 5432?

                                                                                                                                                                                                                                                                                                                                                                                                                                                                                                                                                                             

Traceback (most recent call last):
  File "/home/pi/Desktop/message.py", line 23, in <module>
    conn = psycopg2.connect(database="performance", user='pi', password='Sox2017!', host='192.168.0.235', port= '5432')
  File "/usr/local/lib/python2.7/dist-packages/psycopg2/__init__.py", line 127, in connect
    conn = _connect(dsn, connection_factory=connection_factory, **kwasync)
psycopg2.OperationalError: could not connect to server: Network is unreachable
	Is the server running on host "192.168.0.235" and accepting
	TCP/IP connections on port 5432?



Traceback (most recent call last):
  File "/home/pi/Desktop/message.py", line 23, in <module>
    conn = psycopg2.connect(database="performance", user='pi', password='Sox2017!', host='192.168.0.235', port= '5432')
  File "/usr/local/lib/python2.7/dist-packages/psycopg2/__init__.py", line 127, in connect
    conn = _connect(dsn, connection_factory=connection_factory, **kwasync)
psycopg2.OperationalError: could not connect to server: Network is unreachable
	Is the server running on host "192.168.0.235" and accepting
	TCP/IP connections on port 5432?



Traceback (most recent call last):
  File "/home/pi/Desktop/message.py", line 23, in <module>
    conn = psycopg2.connect(database="performance", user='pi', password='Sox2017!', host='192.168.0.235', port= '5432')
  File "/usr/local/lib/python2.7/dist-packages/psycopg2/__init__.py", line 127, in connect
    conn = _connect(dsn, connection_factory=connection_factory, **kwasync)
psycopg2.OperationalError: could not connect to server: Network is unreachable
	Is the server running on host "192.168.0.235" and accepting
	TCP/IP connections on port 5432?



Traceback (most recent call last):
  File "/home/pi/Desktop/message.py", line 23, in <module>
    conn = psycopg2.connect(database="performance", user='pi', password='Sox2017!', host='192.168.0.235', port= '5432')
  File "/usr/local/lib/python2.7/dist-packages/psycopg2/__init__.py", line 127, in connect
    conn = _connect(dsn, connection_factory=connection_factory, **kwasync)
psycopg2.OperationalError: could not connect to server: Network is unreachable
	Is the server running on host "192.168.0.235" and accepting
	TCP/IP connections on port 5432?



Traceback (most recent call last):
  File "/home/pi/Desktop/message.py", line 23, in <module>
    conn = psycopg2.connect(database="performance", user='pi', password='Sox2017!', host='192.168.0.235', port= '5432')
  File "/usr/local/lib/python2.7/dist-packages/psycopg2/__init__.py", line 127, in connect
    conn = _connect(dsn, connection_factory=connection_factory, **kwasync)
psycopg2.OperationalError: could not connect to server: Network is unreachable
	Is the server running on host "192.168.0.235" and accepting
	TCP/IP connections on port 5432?



Traceback (most recent call last):
  File "/home/pi/Desktop/message.py", line 23, in <module>
    conn = psycopg2.connect(database="performance", user='pi', password='Sox2017!', host='192.168.0.235', port= '5432')
  File "/usr/local/lib/python2.7/dist-packages/psycopg2/__init__.py", line 127, in connect
    conn = _connect(dsn, connection_factory=connection_factory, **kwasync)
psycopg2.OperationalError: could not connect to server: Network is unreachable
	Is the server running on host "192.168.0.235" and accepting
	TCP/IP connections on port 5432?



Traceback (most recent call last):
  File "/home/pi/Desktop/message.py", line 23, in <module>
    conn = psycopg2.connect(database="performance", user='pi', password='Sox2017!', host='192.168.0.235', port= '5432')
  File "/usr/local/lib/python2.7/dist-packages/psycopg2/__init__.py", line 127, in connect
    conn = _connect(dsn, connection_factory=connection_factory, **kwasync)
psycopg2.OperationalError: could not connect to server: Network is unreachable
	Is the server running on host "192.168.0.235" and accepting
	TCP/IP connections on port 5432?



Traceback (most recent call last):
  File "/home/pi/Desktop/message.py", line 23, in <module>
    conn = psycopg2.connect(database="performance", user='pi', password='Sox2017!', host='192.168.0.235', port= '5432')
  File "/usr/local/lib/python2.7/dist-packages/psycopg2/__init__.py", line 127, in connect
    conn = _connect(dsn, connection_factory=connection_factory, **kwasync)
psycopg2.OperationalError: could not connect to server: Network is unreachable
	Is the server running on host "192.168.0.235" and accepting
	TCP/IP connections on port 5432?



Traceback (most recent call last):
  File "/home/pi/Desktop/message.py", line 23, in <module>
    conn = psycopg2.connect(database="performance", user='pi', password='Sox2017!', host='192.168.0.235', port= '5432')
  File "/usr/local/lib/python2.7/dist-packages/psycopg2/__init__.py", line 127, in connect
    conn = _connect(dsn, connection_factory=connection_factory, **kwasync)
psycopg2.OperationalError: could not connect to server: Network is unreachable
	Is the server running on host "192.168.0.235" and accepting
	TCP/IP connections on port 5432?



Traceback (most recent call last):
  File "/home/pi/Desktop/message.py", line 23, in <module>
    conn = psycopg2.connect(database="performance", user='pi', password='Sox2017!', host='192.168.0.235', port= '5432')
  File "/usr/local/lib/python2.7/dist-packages/psycopg2/__init__.py", line 127, in connect
    conn = _connect(dsn, connection_factory=connection_factory, **kwasync)
psycopg2.OperationalError: could not connect to server: Network is unreachable
	Is the server running on host "192.168.0.235" and accepting
	TCP/IP connections on port 5432?



Traceback (most recent call last):
  File "/home/pi/Desktop/message.py", line 23, in <module>
    conn = psycopg2.connect(database="performance", user='pi', password='Sox2017!', host='192.168.0.235', port= '5432')
  File "/usr/local/lib/python2.7/dist-packages/psycopg2/__init__.py", line 127, in connect
    conn = _connect(dsn, connection_factory=connection_factory, **kwasync)
psycopg2.OperationalError: could not connect to server: Network is unreachable
	Is the server running on host "192.168.0.235" and accepting
	TCP/IP connections on port 5432?



Traceback (most recent call last):
  File "/home/pi/Desktop/message.py", line 23, in <module>
    conn = psycopg2.connect(database="performance", user='pi', password='Sox2017!', host='192.168.0.235', port= '5432')
  File "/usr/local/lib/python2.7/dist-packages/psycopg2/__init__.py", line 127, in connect
    conn = _connect(dsn, connection_factory=connection_factory, **kwasync)
psycopg2.OperationalError: could not connect to server: Network is unreachable
	Is the server running on host "192.168.0.235" and accepting
	TCP/IP connections on port 5432?



Traceback (most recent call last):
  File "/home/pi/Desktop/message.py", line 23, in <module>
    conn = psycopg2.connect(database="performance", user='pi', password='Sox2017!', host='192.168.0.235', port= '5432')
  File "/usr/local/lib/python2.7/dist-packages/psycopg2/__init__.py", line 127, in connect
    conn = _connect(dsn, connection_factory=connection_factory, **kwasync)
psycopg2.OperationalError: could not connect to server: Network is unreachable
	Is the server running on host "192.168.0.235" and accepting
	TCP/IP connections on port 5432?



Traceback (most recent call last):
  File "/home/pi/Desktop/message.py", line 23, in <module>
    conn = psycopg2.connect(database="performance", user='pi', password='Sox2017!', host='192.168.0.235', port= '5432')
  File "/usr/local/lib/python2.7/dist-packages/psycopg2/__init__.py", line 127, in connect
    conn = _connect(dsn, connection_factory=connection_factory, **kwasync)
psycopg2.OperationalError: could not connect to server: Network is unreachable
	Is the server running on host "192.168.0.235" and accepting
	TCP/IP connections on port 5432?



Traceback (most recent call last):
  File "/home/pi/Desktop/message.py", line 23, in <module>
    conn = psycopg2.connect(database="performance", user='pi', password='Sox2017!', host='192.168.0.235', port= '5432')
  File "/usr/local/lib/python2.7/dist-packages/psycopg2/__init__.py", line 127, in connect
    conn = _connect(dsn, connection_factory=connection_factory, **kwasync)
psycopg2.OperationalError: could not connect to server: Network is unreachable
	Is the server running on host "192.168.0.235" and accepting
	TCP/IP connections on port 5432?



Traceback (most recent call last):
  File "/home/pi/Desktop/message.py", line 23, in <module>
    conn = psycopg2.connect(database="performance", user='pi', password='Sox2017!', host='192.168.0.235', port= '5432')
  File "/usr/local/lib/python2.7/dist-packages/psycopg2/__init__.py", line 127, in connect
    conn = _connect(dsn, connection_factory=connection_factory, **kwasync)
psycopg2.OperationalError: could not connect to server: Network is unreachable
	Is the server running on host "192.168.0.235" and accepting
	TCP/IP connections on port 5432?



Traceback (most recent call last):
  File "/home/pi/Desktop/message.py", line 23, in <module>
    conn = psycopg2.connect(database="performance", user='pi', password='Sox2017!', host='192.168.0.235', port= '5432')
  File "/usr/local/lib/python2.7/dist-packages/psycopg2/__init__.py", line 127, in connect
    conn = _connect(dsn, connection_factory=connection_factory, **kwasync)
psycopg2.OperationalError: could not connect to server: Network is unreachable
	Is the server running on host "192.168.0.235" and accepting
	TCP/IP connections on port 5432?



Traceback (most recent call last):
  File "/home/pi/Desktop/message.py", line 23, in <module>
    conn = psycopg2.connect(database="performance", user='pi', password='Sox2017!', host='192.168.0.235', port= '5432')
  File "/usr/local/lib/python2.7/dist-packages/psycopg2/__init__.py", line 127, in connect
    conn = _connect(dsn, connection_factory=connection_factory, **kwasync)
psycopg2.OperationalError: could not connect to server: Network is unreachable
	Is the server running on host "192.168.0.235" and accepting
	TCP/IP connections on port 5432?



Traceback (most recent call last):
  File "/home/pi/Desktop/message.py", line 23, in <module>
    conn = psycopg2.connect(database="performance", user='pi', password='Sox2017!', host='192.168.0.235', port= '5432')
  File "/usr/local/lib/python2.7/dist-packages/psycopg2/__init__.py", line 127, in connect
    conn = _connect(dsn, connection_factory=connection_factory, **kwasync)
psycopg2.OperationalError: could not connect to server: Network is unreachable
	Is the server running on host "192.168.0.235" and accepting
	TCP/IP connections on port 5432?



Traceback (most recent call last):
  File "/home/pi/Desktop/message.py", line 23, in <module>
    conn = psycopg2.connect(database="performance", user='pi', password='Sox2017!', host='192.168.0.235', port= '5432')
  File "/usr/local/lib/python2.7/dist-packages/psycopg2/__init__.py", line 127, in connect
    conn = _connect(dsn, connection_factory=connection_factory, **kwasync)
psycopg2.OperationalError: could not connect to server: Network is unreachable
	Is the server running on host "192.168.0.235" and accepting
	TCP/IP connections on port 5432?



Traceback (most recent call last):
  File "/home/pi/Desktop/message.py", line 23, in <module>
    conn = psycopg2.connect(database="performance", user='pi', password='Sox2017!', host='192.168.0.235', port= '5432')
  File "/usr/local/lib/python2.7/dist-packages/psycopg2/__init__.py", line 127, in connect
    conn = _connect(dsn, connection_factory=connection_factory, **kwasync)
psycopg2.OperationalError: could not connect to server: Network is unreachable
	Is the server running on host "192.168.0.235" and accepting
	TCP/IP connections on port 5432?



Traceback (most recent call last):
  File "/home/pi/Desktop/message.py", line 23, in <module>
    conn = psycopg2.connect(database="performance", user='pi', password='Sox2017!', host='192.168.0.235', port= '5432')
  File "/usr/local/lib/python2.7/dist-packages/psycopg2/__init__.py", line 127, in connect
    conn = _connect(dsn, connection_factory=connection_factory, **kwasync)
psycopg2.OperationalError: could not connect to server: Network is unreachable
	Is the server running on host "192.168.0.235" and accepting
	TCP/IP connections on port 5432?



Traceback (most recent call last):
  File "/home/pi/Desktop/message.py", line 23, in <module>
    conn = psycopg2.connect(database="performance", user='pi', password='Sox2017!', host='192.168.0.235', port= '5432')
  File "/usr/local/lib/python2.7/dist-packages/psycopg2/__init__.py", line 127, in connect
    conn = _connect(dsn, connection_factory=connection_factory, **kwasync)
psycopg2.OperationalError: could not connect to server: Network is unreachable
	Is the server running on host "192.168.0.235" and accepting
	TCP/IP connections on port 5432?



Traceback (most recent call last):
  File "/home/pi/Desktop/message.py", line 23, in <module>
    conn = psycopg2.connect(database="performance", user='pi', password='Sox2017!', host='192.168.0.235', port= '5432')
  File "/usr/local/lib/python2.7/dist-packages/psycopg2/__init__.py", line 127, in connect
    conn = _connect(dsn, connection_factory=connection_factory, **kwasync)
psycopg2.OperationalError: could not connect to server: Network is unreachable
	Is the server running on host "192.168.0.235" and accepting
	TCP/IP connections on port 5432?



Traceback (most recent call last):
  File "/home/pi/Desktop/message.py", line 23, in <module>
    conn = psycopg2.connect(database="performance", user='pi', password='Sox2017!', host='192.168.0.235', port= '5432')
  File "/usr/local/lib/python2.7/dist-packages/psycopg2/__init__.py", line 127, in connect
    conn = _connect(dsn, connection_factory=connection_factory, **kwasync)
psycopg2.OperationalError: could not connect to server: Network is unreachable
	Is the server running on host "192.168.0.235" and accepting
	TCP/IP connections on port 5432?



Traceback (most recent call last):
  File "/home/pi/Desktop/message.py", line 23, in <module>
    conn = psycopg2.connect(database="performance", user='pi', password='Sox2017!', host='192.168.0.235', port= '5432')
  File "/usr/local/lib/python2.7/dist-packages/psycopg2/__init__.py", line 127, in connect
    conn = _connect(dsn, connection_factory=connection_factory, **kwasync)
psycopg2.OperationalError: could not connect to server: Network is unreachable
	Is the server running on host "192.168.0.235" and accepting
	TCP/IP connections on port 5432?



Traceback (most recent call last):
  File "/home/pi/Desktop/message.py", line 23, in <module>
    conn = psycopg2.connect(database="performance", user='pi', password='Sox2017!', host='192.168.0.235', port= '5432')
  File "/usr/local/lib/python2.7/dist-packages/psycopg2/__init__.py", line 127, in connect
    conn = _connect(dsn, connection_factory=connection_factory, **kwasync)
psycopg2.OperationalError: could not connect to server: Network is unreachable
	Is the server running on host "192.168.0.235" and accepting
	TCP/IP connections on port 5432?



Traceback (most recent call last):
  File "/home/pi/Desktop/message.py", line 23, in <module>
    conn = psycopg2.connect(database="performance", user='pi', password='Sox2017!', host='192.168.0.235', port= '5432')
  File "/usr/local/lib/python2.7/dist-packages/psycopg2/__init__.py", line 127, in connect
    conn = _connect(dsn, connection_factory=connection_factory, **kwasync)
psycopg2.OperationalError: could not connect to server: Network is unreachable
	Is the server running on host "192.168.0.235" and accepting
	TCP/IP connections on port 5432?



Traceback (most recent call last):
  File "/home/pi/Desktop/message.py", line 23, in <module>
    conn = psycopg2.connect(database="performance", user='pi', password='Sox2017!', host='192.168.0.235', port= '5432')
  File "/usr/local/lib/python2.7/dist-packages/psycopg2/__init__.py", line 127, in connect
    conn = _connect(dsn, connection_factory=connection_factory, **kwasync)
psycopg2.OperationalError: could not connect to server: Network is unreachable
	Is the server running on host "192.168.0.235" and accepting
	TCP/IP connections on port 5432?



Traceback (most recent call last):
  File "/home/pi/Desktop/message.py", line 23, in <module>
    conn = psycopg2.connect(database="performance", user='pi', password='Sox2017!', host='192.168.0.235', port= '5432')
  File "/usr/local/lib/python2.7/dist-packages/psycopg2/__init__.py", line 127, in connect
    conn = _connect(dsn, connection_factory=connection_factory, **kwasync)
psycopg2.OperationalError: could not connect to server: Network is unreachable
	Is the server running on host "192.168.0.235" and accepting
	TCP/IP connections on port 5432?



Traceback (most recent call last):
  File "/home/pi/Desktop/message.py", line 23, in <module>
    conn = psycopg2.connect(database="performance", user='pi', password='Sox2017!', host='192.168.0.235', port= '5432')
  File "/usr/local/lib/python2.7/dist-packages/psycopg2/__init__.py", line 127, in connect
    conn = _connect(dsn, connection_factory=connection_factory, **kwasync)
psycopg2.OperationalError: could not connect to server: Network is unreachable
	Is the server running on host "192.168.0.235" and accepting
	TCP/IP connections on port 5432?



Traceback (most recent call last):
  File "/home/pi/Desktop/message.py", line 23, in <module>
    conn = psycopg2.connect(database="performance", user='pi', password='Sox2017!', host='192.168.0.235', port= '5432')
  File "/usr/local/lib/python2.7/dist-packages/psycopg2/__init__.py", line 127, in connect
    conn = _connect(dsn, connection_factory=connection_factory, **kwasync)
psycopg2.OperationalError: could not connect to server: Network is unreachable
	Is the server running on host "192.168.0.235" and accepting
	TCP/IP connections on port 5432?



Traceback (most recent call last):
  File "/home/pi/Desktop/message.py", line 23, in <module>
    conn = psycopg2.connect(database="performance", user='pi', password='Sox2017!', host='192.168.0.235', port= '5432')
  File "/usr/local/lib/python2.7/dist-packages/psycopg2/__init__.py", line 127, in connect
    conn = _connect(dsn, connection_factory=connection_factory, **kwasync)
psycopg2.OperationalError: could not connect to server: Network is unreachable
	Is the server running on host "192.168.0.235" and accepting
	TCP/IP connections on port 5432?



Traceback (most recent call last):
  File "/home/pi/Desktop/message.py", line 23, in <module>
    conn = psycopg2.connect(database="performance", user='pi', password='Sox2017!', host='192.168.0.235', port= '5432')
  File "/usr/local/lib/python2.7/dist-packages/psycopg2/__init__.py", line 127, in connect
    conn = _connect(dsn, connection_factory=connection_factory, **kwasync)
psycopg2.OperationalError: could not connect to server: Network is unreachable
	Is the server running on host "192.168.0.235" and accepting
	TCP/IP connections on port 5432?



Traceback (most recent call last):
  File "/home/pi/Desktop/message.py", line 23, in <module>
    conn = psycopg2.connect(database="performance", user='pi', password='Sox2017!', host='192.168.0.235', port= '5432')
  File "/usr/local/lib/python2.7/dist-packages/psycopg2/__init__.py", line 127, in connect
    conn = _connect(dsn, connection_factory=connection_factory, **kwasync)
psycopg2.OperationalError: could not connect to server: Network is unreachable
	Is the server running on host "192.168.0.235" and accepting
	TCP/IP connections on port 5432?



Traceback (most recent call last):
  File "/home/pi/Desktop/message.py", line 23, in <module>
    conn = psycopg2.connect(database="performance", user='pi', password='Sox2017!', host='192.168.0.235', port= '5432')
  File "/usr/local/lib/python2.7/dist-packages/psycopg2/__init__.py", line 127, in connect
    conn = _connect(dsn, connection_factory=connection_factory, **kwasync)
psycopg2.OperationalError: could not connect to server: Network is unreachable
	Is the server running on host "192.168.0.235" and accepting
	TCP/IP connections on port 5432?



Traceback (most recent call last):
  File "/home/pi/Desktop/message.py", line 23, in <module>
    conn = psycopg2.connect(database="performance", user='pi', password='Sox2017!', host='192.168.0.235', port= '5432')
  File "/usr/local/lib/python2.7/dist-packages/psycopg2/__init__.py", line 127, in connect
    conn = _connect(dsn, connection_factory=connection_factory, **kwasync)
psycopg2.OperationalError: could not connect to server: Network is unreachable
	Is the server running on host "192.168.0.235" and accepting
	TCP/IP connections on port 5432?



Traceback (most recent call last):
  File "/home/pi/Desktop/message.py", line 23, in <module>
    conn = psycopg2.connect(database="performance", user='pi', password='Sox2017!', host='192.168.0.235', port= '5432')
  File "/usr/local/lib/python2.7/dist-packages/psycopg2/__init__.py", line 127, in connect
    conn = _connect(dsn, connection_factory=connection_factory, **kwasync)
psycopg2.OperationalError: could not connect to server: Network is unreachable
	Is the server running on host "192.168.0.235" and accepting
	TCP/IP connections on port 5432?



Traceback (most recent call last):
  File "/home/pi/Desktop/message.py", line 23, in <module>
    conn = psycopg2.connect(database="performance", user='pi', password='Sox2017!', host='192.168.0.235', port= '5432')
  File "/usr/local/lib/python2.7/dist-packages/psycopg2/__init__.py", line 127, in connect
    conn = _connect(dsn, connection_factory=connection_factory, **kwasync)
psycopg2.OperationalError: could not connect to server: Network is unreachable
	Is the server running on host "192.168.0.235" and accepting
	TCP/IP connections on port 5432?



Traceback (most recent call last):
  File "/home/pi/Desktop/message.py", line 23, in <module>
    conn = psycopg2.connect(database="performance", user='pi', password='Sox2017!', host='192.168.0.235', port= '5432')
  File "/usr/local/lib/python2.7/dist-packages/psycopg2/__init__.py", line 127, in connect
    conn = _connect(dsn, connection_factory=connection_factory, **kwasync)
psycopg2.OperationalError: could not connect to server: Network is unreachable
	Is the server running on host "192.168.0.235" and accepting
	TCP/IP connections on port 5432?



Traceback (most recent call last):
  File "/home/pi/Desktop/message.py", line 23, in <module>
    conn = psycopg2.connect(database="performance", user='pi', password='Sox2017!', host='192.168.0.235', port= '5432')
  File "/usr/local/lib/python2.7/dist-packages/psycopg2/__init__.py", line 127, in connect
    conn = _connect(dsn, connection_factory=connection_factory, **kwasync)
psycopg2.OperationalError: could not connect to server: Network is unreachable
	Is the server running on host "192.168.0.235" and accepting
	TCP/IP connections on port 5432?



Traceback (most recent call last):
  File "/home/pi/Desktop/message.py", line 23, in <module>
    conn = psycopg2.connect(database="performance", user='pi', password='Sox2017!', host='192.168.0.235', port= '5432')
  File "/usr/local/lib/python2.7/dist-packages/psycopg2/__init__.py", line 127, in connect
    conn = _connect(dsn, connection_factory=connection_factory, **kwasync)
psycopg2.OperationalError: could not connect to server: Network is unreachable
	Is the server running on host "192.168.0.235" and accepting
	TCP/IP connections on port 5432?



Traceback (most recent call last):
  File "/home/pi/Desktop/message.py", line 23, in <module>
    conn = psycopg2.connect(database="performance", user='pi', password='Sox2017!', host='192.168.0.235', port= '5432')
  File "/usr/local/lib/python2.7/dist-packages/psycopg2/__init__.py", line 127, in connect
    conn = _connect(dsn, connection_factory=connection_factory, **kwasync)
psycopg2.OperationalError: could not connect to server: Network is unreachable
	Is the server running on host "192.168.0.235" and accepting
	TCP/IP connections on port 5432?



Traceback (most recent call last):
  File "/home/pi/Desktop/message.py", line 23, in <module>
    conn = psycopg2.connect(database="performance", user='pi', password='Sox2017!', host='192.168.0.235', port= '5432')
  File "/usr/local/lib/python2.7/dist-packages/psycopg2/__init__.py", line 127, in connect
    conn = _connect(dsn, connection_factory=connection_factory, **kwasync)
psycopg2.OperationalError: could not connect to server: Network is unreachable
	Is the server running on host "192.168.0.235" and accepting
	TCP/IP connections on port 5432?



Traceback (most recent call last):
  File "/home/pi/Desktop/message.py", line 23, in <module>
    conn = psycopg2.connect(database="performance", user='pi', password='Sox2017!', host='192.168.0.235', port= '5432')
  File "/usr/local/lib/python2.7/dist-packages/psycopg2/__init__.py", line 127, in connect
    conn = _connect(dsn, connection_factory=connection_factory, **kwasync)
psycopg2.OperationalError: could not connect to server: Network is unreachable
	Is the server running on host "192.168.0.235" and accepting
	TCP/IP connections on port 5432?



Traceback (most recent call last):
  File "/home/pi/Desktop/message.py", line 23, in <module>
    conn = psycopg2.connect(database="performance", user='pi', password='Sox2017!', host='192.168.0.235', port= '5432')
  File "/usr/local/lib/python2.7/dist-packages/psycopg2/__init__.py", line 127, in connect
    conn = _connect(dsn, connection_factory=connection_factory, **kwasync)
psycopg2.OperationalError: could not connect to server: Network is unreachable
	Is the server running on host "192.168.0.235" and accepting
	TCP/IP connections on port 5432?



Traceback (most recent call last):
  File "/home/pi/Desktop/message.py", line 23, in <module>
    conn = psycopg2.connect(database="performance", user='pi', password='Sox2017!', host='192.168.0.235', port= '5432')
  File "/usr/local/lib/python2.7/dist-packages/psycopg2/__init__.py", line 127, in connect
    conn = _connect(dsn, connection_factory=connection_factory, **kwasync)
psycopg2.OperationalError: could not connect to server: Network is unreachable
	Is the server running on host "192.168.0.235" and accepting
	TCP/IP connections on port 5432?



Traceback (most recent call last):
  File "/home/pi/Desktop/message.py", line 23, in <module>
    conn = psycopg2.connect(database="performance", user='pi', password='Sox2017!', host='192.168.0.235', port= '5432')
  File "/usr/local/lib/python2.7/dist-packages/psycopg2/__init__.py", line 127, in connect
    conn = _connect(dsn, connection_factory=connection_factory, **kwasync)
psycopg2.OperationalError: could not connect to server: Network is unreachable
	Is the server running on host "192.168.0.235" and accepting
	TCP/IP connections on port 5432?



Traceback (most recent call last):
  File "/home/pi/Desktop/message.py", line 23, in <module>
    conn = psycopg2.connect(database="performance", user='pi', password='Sox2017!', host='192.168.0.235', port= '5432')
  File "/usr/local/lib/python2.7/dist-packages/psycopg2/__init__.py", line 127, in connect
    conn = _connect(dsn, connection_factory=connection_factory, **kwasync)
psycopg2.OperationalError: could not connect to server: Network is unreachable
	Is the server running on host "192.168.0.235" and accepting
	TCP/IP connections on port 5432?



Traceback (most recent call last):
  File "/home/pi/Desktop/message.py", line 23, in <module>
    conn = psycopg2.connect(database="performance", user='pi', password='Sox2017!', host='192.168.0.235', port= '5432')
  File "/usr/local/lib/python2.7/dist-packages/psycopg2/__init__.py", line 127, in connect
    conn = _connect(dsn, connection_factory=connection_factory, **kwasync)
psycopg2.OperationalError: could not connect to server: Network is unreachable
	Is the server running on host "192.168.0.235" and accepting
	TCP/IP connections on port 5432?



Traceback (most recent call last):
  File "/home/pi/Desktop/message.py", line 23, in <module>
    conn = psycopg2.connect(database="performance", user='pi', password='Sox2017!', host='192.168.0.235', port= '5432')
  File "/usr/local/lib/python2.7/dist-packages/psycopg2/__init__.py", line 127, in connect
    conn = _connect(dsn, connection_factory=connection_factory, **kwasync)
psycopg2.OperationalError: could not connect to server: Network is unreachable
	Is the server running on host "192.168.0.235" and accepting
	TCP/IP connections on port 5432?



Traceback (most recent call last):
  File "/home/pi/Desktop/message.py", line 23, in <module>
    conn = psycopg2.connect(database="performance", user='pi', password='Sox2017!', host='192.168.0.235', port= '5432')
  File "/usr/local/lib/python2.7/dist-packages/psycopg2/__init__.py", line 127, in connect
    conn = _connect(dsn, connection_factory=connection_factory, **kwasync)
psycopg2.OperationalError: could not connect to server: Network is unreachable
	Is the server running on host "192.168.0.235" and accepting
	TCP/IP connections on port 5432?



Traceback (most recent call last):
  File "/home/pi/Desktop/message.py", line 23, in <module>
    conn = psycopg2.connect(database="performance", user='pi', password='Sox2017!', host='192.168.0.235', port= '5432')
  File "/usr/local/lib/python2.7/dist-packages/psycopg2/__init__.py", line 127, in connect
    conn = _connect(dsn, connection_factory=connection_factory, **kwasync)
psycopg2.OperationalError: could not connect to server: Network is unreachable
	Is the server running on host "192.168.0.235" and accepting
	TCP/IP connections on port 5432?



Traceback (most recent call last):
  File "/home/pi/Desktop/message.py", line 23, in <module>
    conn = psycopg2.connect(database="performance", user='pi', password='Sox2017!', host='192.168.0.235', port= '5432')
  File "/usr/local/lib/python2.7/dist-packages/psycopg2/__init__.py", line 127, in connect
    conn = _connect(dsn, connection_factory=connection_factory, **kwasync)
psycopg2.OperationalError: could not connect to server: Network is unreachable
	Is the server running on host "192.168.0.235" and accepting
	TCP/IP connections on port 5432?



Traceback (most recent call last):
  File "/home/pi/Desktop/message.py", line 23, in <module>
    conn = psycopg2.connect(database="performance", user='pi', password='Sox2017!', host='192.168.0.235', port= '5432')
  File "/usr/local/lib/python2.7/dist-packages/psycopg2/__init__.py", line 127, in connect
    conn = _connect(dsn, connection_factory=connection_factory, **kwasync)
psycopg2.OperationalError: could not connect to server: Network is unreachable
	Is the server running on host "192.168.0.235" and accepting
	TCP/IP connections on port 5432?



Traceback (most recent call last):
  File "/home/pi/Desktop/message.py", line 23, in <module>
    conn = psycopg2.connect(database="performance", user='pi', password='Sox2017!', host='192.168.0.235', port= '5432')
  File "/usr/local/lib/python2.7/dist-packages/psycopg2/__init__.py", line 127, in connect
    conn = _connect(dsn, connection_factory=connection_factory, **kwasync)
psycopg2.OperationalError: could not connect to server: Network is unreachable
	Is the server running on host "192.168.0.235" and accepting
	TCP/IP connections on port 5432?



Traceback (most recent call last):
  File "/home/pi/Desktop/message.py", line 23, in <module>
    conn = psycopg2.connect(database="performance", user='pi', password='Sox2017!', host='192.168.0.235', port= '5432')
  File "/usr/local/lib/python2.7/dist-packages/psycopg2/__init__.py", line 127, in connect
    conn = _connect(dsn, connection_factory=connection_factory, **kwasync)
psycopg2.OperationalError: could not connect to server: Network is unreachable
	Is the server running on host "192.168.0.235" and accepting
	TCP/IP connections on port 5432?



Traceback (most recent call last):
  File "/home/pi/Desktop/message.py", line 23, in <module>
    conn = psycopg2.connect(database="performance", user='pi', password='Sox2017!', host='192.168.0.235', port= '5432')
  File "/usr/local/lib/python2.7/dist-packages/psycopg2/__init__.py", line 127, in connect
    conn = _connect(dsn, connection_factory=connection_factory, **kwasync)
psycopg2.OperationalError: could not connect to server: Network is unreachable
	Is the server running on host "192.168.0.235" and accepting
	TCP/IP connections on port 5432?



Traceback (most recent call last):
  File "/home/pi/Desktop/message.py", line 23, in <module>
    conn = psycopg2.connect(database="performance", user='pi', password='Sox2017!', host='192.168.0.235', port= '5432')
  File "/usr/local/lib/python2.7/dist-packages/psycopg2/__init__.py", line 127, in connect
    conn = _connect(dsn, connection_factory=connection_factory, **kwasync)
psycopg2.OperationalError: could not connect to server: Network is unreachable
	Is the server running on host "192.168.0.235" and accepting
	TCP/IP connections on port 5432?



Traceback (most recent call last):
  File "/home/pi/Desktop/message.py", line 23, in <module>
    conn = psycopg2.connect(database="performance", user='pi', password='Sox2017!', host='192.168.0.235', port= '5432')
  File "/usr/local/lib/python2.7/dist-packages/psycopg2/__init__.py", line 127, in connect
    conn = _connect(dsn, connection_factory=connection_factory, **kwasync)
psycopg2.OperationalError: could not connect to server: Network is unreachable
	Is the server running on host "192.168.0.235" and accepting
	TCP/IP connections on port 5432?



Traceback (most recent call last):
  File "/home/pi/Desktop/message.py", line 23, in <module>
    conn = psycopg2.connect(database="performance", user='pi', password='Sox2017!', host='192.168.0.235', port= '5432')
  File "/usr/local/lib/python2.7/dist-packages/psycopg2/__init__.py", line 127, in connect
    conn = _connect(dsn, connection_factory=connection_factory, **kwasync)
psycopg2.OperationalError: could not connect to server: Network is unreachable
	Is the server running on host "192.168.0.235" and accepting
	TCP/IP connections on port 5432?



Traceback (most recent call last):
  File "/home/pi/Desktop/message.py", line 23, in <module>
    conn = psycopg2.connect(database="performance", user='pi', password='Sox2017!', host='192.168.0.235', port= '5432')
  File "/usr/local/lib/python2.7/dist-packages/psycopg2/__init__.py", line 127, in connect
    conn = _connect(dsn, connection_factory=connection_factory, **kwasync)
psycopg2.OperationalError: could not connect to server: Network is unreachable
	Is the server running on host "192.168.0.235" and accepting
	TCP/IP connections on port 5432?



Traceback (most recent call last):
  File "/home/pi/Desktop/message.py", line 23, in <module>
    conn = psycopg2.connect(database="performance", user='pi', password='Sox2017!', host='192.168.0.235', port= '5432')
  File "/usr/local/lib/python2.7/dist-packages/psycopg2/__init__.py", line 127, in connect
    conn = _connect(dsn, connection_factory=connection_factory, **kwasync)
psycopg2.OperationalError: could not connect to server: Network is unreachable
	Is the server running on host "192.168.0.235" and accepting
	TCP/IP connections on port 5432?



Traceback (most recent call last):
  File "/home/pi/Desktop/message.py", line 23, in <module>
    conn = psycopg2.connect(database="performance", user='pi', password='Sox2017!', host='192.168.0.235', port= '5432')
  File "/usr/local/lib/python2.7/dist-packages/psycopg2/__init__.py", line 127, in connect
    conn = _connect(dsn, connection_factory=connection_factory, **kwasync)
psycopg2.OperationalError: could not connect to server: Network is unreachable
	Is the server running on host "192.168.0.235" and accepting
	TCP/IP connections on port 5432?



Traceback (most recent call last):
  File "/home/pi/Desktop/message.py", line 23, in <module>
    conn = psycopg2.connect(database="performance", user='pi', password='Sox2017!', host='192.168.0.235', port= '5432')
  File "/usr/local/lib/python2.7/dist-packages/psycopg2/__init__.py", line 127, in connect
    conn = _connect(dsn, connection_factory=connection_factory, **kwasync)
psycopg2.OperationalError: could not connect to server: Network is unreachable
	Is the server running on host "192.168.0.235" and accepting
	TCP/IP connections on port 5432?



Traceback (most recent call last):
  File "/home/pi/Desktop/message.py", line 23, in <module>
    conn = psycopg2.connect(database="performance", user='pi', password='Sox2017!', host='192.168.0.235', port= '5432')
  File "/usr/local/lib/python2.7/dist-packages/psycopg2/__init__.py", line 127, in connect
    conn = _connect(dsn, connection_factory=connection_factory, **kwasync)
psycopg2.OperationalError: could not connect to server: Network is unreachable
	Is the server running on host "192.168.0.235" and accepting
	TCP/IP connections on port 5432?



Traceback (most recent call last):
  File "/home/pi/Desktop/message.py", line 23, in <module>
    conn = psycopg2.connect(database="performance", user='pi', password='Sox2017!', host='192.168.0.235', port= '5432')
  File "/usr/local/lib/python2.7/dist-packages/psycopg2/__init__.py", line 127, in connect
    conn = _connect(dsn, connection_factory=connection_factory, **kwasync)
psycopg2.OperationalError: could not connect to server: Network is unreachable
	Is the server running on host "192.168.0.235" and accepting
	TCP/IP connections on port 5432?



Traceback (most recent call last):
  File "/home/pi/Desktop/message.py", line 23, in <module>
    conn = psycopg2.connect(database="performance", user='pi', password='Sox2017!', host='192.168.0.235', port= '5432')
  File "/usr/local/lib/python2.7/dist-packages/psycopg2/__init__.py", line 127, in connect
    conn = _connect(dsn, connection_factory=connection_factory, **kwasync)
psycopg2.OperationalError: could not connect to server: Network is unreachable
	Is the server running on host "192.168.0.235" and accepting
	TCP/IP connections on port 5432?



Traceback (most recent call last):
  File "/home/pi/Desktop/message.py", line 23, in <module>
    conn = psycopg2.connect(database="performance", user='pi', password='Sox2017!', host='192.168.0.235', port= '5432')
  File "/usr/local/lib/python2.7/dist-packages/psycopg2/__init__.py", line 127, in connect
    conn = _connect(dsn, connection_factory=connection_factory, **kwasync)
psycopg2.OperationalError: could not connect to server: Network is unreachable
	Is the server running on host "192.168.0.235" and accepting
	TCP/IP connections on port 5432?



Traceback (most recent call last):
  File "/home/pi/Desktop/message.py", line 23, in <module>
    conn = psycopg2.connect(database="performance", user='pi', password='Sox2017!', host='192.168.0.235', port= '5432')
  File "/usr/local/lib/python2.7/dist-packages/psycopg2/__init__.py", line 127, in connect
    conn = _connect(dsn, connection_factory=connection_factory, **kwasync)
psycopg2.OperationalError: could not connect to server: Network is unreachable
	Is the server running on host "192.168.0.235" and accepting
	TCP/IP connections on port 5432?



Traceback (most recent call last):
  File "/home/pi/Desktop/message.py", line 23, in <module>
    conn = psycopg2.connect(database="performance", user='pi', password='Sox2017!', host='192.168.0.235', port= '5432')
  File "/usr/local/lib/python2.7/dist-packages/psycopg2/__init__.py", line 127, in connect
    conn = _connect(dsn, connection_factory=connection_factory, **kwasync)
psycopg2.OperationalError: could not connect to server: Network is unreachable
	Is the server running on host "192.168.0.235" and accepting
	TCP/IP connections on port 5432?



Traceback (most recent call last):
  File "/home/pi/Desktop/message.py", line 23, in <module>
    conn = psycopg2.connect(database="performance", user='pi', password='Sox2017!', host='192.168.0.235', port= '5432')
  File "/usr/local/lib/python2.7/dist-packages/psycopg2/__init__.py", line 127, in connect
    conn = _connect(dsn, connection_factory=connection_factory, **kwasync)
psycopg2.OperationalError: could not connect to server: Network is unreachable
	Is the server running on host "192.168.0.235" and accepting
	TCP/IP connections on port 5432?



Traceback (most recent call last):
  File "/home/pi/Desktop/message.py", line 23, in <module>
    conn = psycopg2.connect(database="performance", user='pi', password='Sox2017!', host='192.168.0.235', port= '5432')
  File "/usr/local/lib/python2.7/dist-packages/psycopg2/__init__.py", line 127, in connect
    conn = _connect(dsn, connection_factory=connection_factory, **kwasync)
psycopg2.OperationalError: could not connect to server: Network is unreachable
	Is the server running on host "192.168.0.235" and accepting
	TCP/IP connections on port 5432?



Traceback (most recent call last):
  File "/home/pi/Desktop/message.py", line 23, in <module>
    conn = psycopg2.connect(database="performance", user='pi', password='Sox2017!', host='192.168.0.235', port= '5432')
  File "/usr/local/lib/python2.7/dist-packages/psycopg2/__init__.py", line 127, in connect
    conn = _connect(dsn, connection_factory=connection_factory, **kwasync)
psycopg2.OperationalError: could not connect to server: Network is unreachable
	Is the server running on host "192.168.0.235" and accepting
	TCP/IP connections on port 5432?



Traceback (most recent call last):
  File "/home/pi/Desktop/message.py", line 23, in <module>
    conn = psycopg2.connect(database="performance", user='pi', password='Sox2017!', host='192.168.0.235', port= '5432')
  File "/usr/local/lib/python2.7/dist-packages/psycopg2/__init__.py", line 127, in connect
    conn = _connect(dsn, connection_factory=connection_factory, **kwasync)
psycopg2.OperationalError: could not connect to server: Network is unreachable
	Is the server running on host "192.168.0.235" and accepting
	TCP/IP connections on port 5432?



Traceback (most recent call last):
  File "/home/pi/Desktop/message.py", line 23, in <module>
    conn = psycopg2.connect(database="performance", user='pi', password='Sox2017!', host='192.168.0.235', port= '5432')
  File "/usr/local/lib/python2.7/dist-packages/psycopg2/__init__.py", line 127, in connect
    conn = _connect(dsn, connection_factory=connection_factory, **kwasync)
psycopg2.OperationalError: could not connect to server: Network is unreachable
	Is the server running on host "192.168.0.235" and accepting
	TCP/IP connections on port 5432?



Traceback (most recent call last):
  File "/home/pi/Desktop/message.py", line 23, in <module>
    conn = psycopg2.connect(database="performance", user='pi', password='Sox2017!', host='192.168.0.235', port= '5432')
  File "/usr/local/lib/python2.7/dist-packages/psycopg2/__init__.py", line 127, in connect
    conn = _connect(dsn, connection_factory=connection_factory, **kwasync)
psycopg2.OperationalError: could not connect to server: Network is unreachable
	Is the server running on host "192.168.0.235" and accepting
	TCP/IP connections on port 5432?



Traceback (most recent call last):
  File "/home/pi/Desktop/message.py", line 23, in <module>
    conn = psycopg2.connect(database="performance", user='pi', password='Sox2017!', host='192.168.0.235', port= '5432')
  File "/usr/local/lib/python2.7/dist-packages/psycopg2/__init__.py", line 127, in connect
    conn = _connect(dsn, connection_factory=connection_factory, **kwasync)
psycopg2.OperationalError: could not connect to server: Network is unreachable
	Is the server running on host "192.168.0.235" and accepting
	TCP/IP connections on port 5432?



Traceback (most recent call last):
  File "/home/pi/Desktop/message.py", line 23, in <module>
    conn = psycopg2.connect(database="performance", user='pi', password='Sox2017!', host='192.168.0.235', port= '5432')
  File "/usr/local/lib/python2.7/dist-packages/psycopg2/__init__.py", line 127, in connect
    conn = _connect(dsn, connection_factory=connection_factory, **kwasync)
psycopg2.OperationalError: could not connect to server: Network is unreachable
	Is the server running on host "192.168.0.235" and accepting
	TCP/IP connections on port 5432?



Traceback (most recent call last):
  File "/home/pi/Desktop/message.py", line 23, in <module>
    conn = psycopg2.connect(database="performance", user='pi', password='Sox2017!', host='192.168.0.235', port= '5432')
  File "/usr/local/lib/python2.7/dist-packages/psycopg2/__init__.py", line 127, in connect
    conn = _connect(dsn, connection_factory=connection_factory, **kwasync)
psycopg2.OperationalError: could not connect to server: Network is unreachable
	Is the server running on host "192.168.0.235" and accepting
	TCP/IP connections on port 5432?



Traceback (most recent call last):
  File "/home/pi/Desktop/message.py", line 23, in <module>
    conn = psycopg2.connect(database="performance", user='pi', password='Sox2017!', host='192.168.0.235', port= '5432')
  File "/usr/local/lib/python2.7/dist-packages/psycopg2/__init__.py", line 127, in connect
    conn = _connect(dsn, connection_factory=connection_factory, **kwasync)
psycopg2.OperationalError: could not connect to server: Network is unreachable
	Is the server running on host "192.168.0.235" and accepting
	TCP/IP connections on port 5432?



Traceback (most recent call last):
  File "/home/pi/Desktop/message.py", line 23, in <module>
    conn = psycopg2.connect(database="performance", user='pi', password='Sox2017!', host='192.168.0.235', port= '5432')
  File "/usr/local/lib/python2.7/dist-packages/psycopg2/__init__.py", line 127, in connect
    conn = _connect(dsn, connection_factory=connection_factory, **kwasync)
psycopg2.OperationalError: could not connect to server: Network is unreachable
	Is the server running on host "192.168.0.235" and accepting
	TCP/IP connections on port 5432?



Traceback (most recent call last):
  File "/home/pi/Desktop/message.py", line 23, in <module>
    conn = psycopg2.connect(database="performance", user='pi', password='Sox2017!', host='192.168.0.235', port= '5432')
  File "/usr/local/lib/python2.7/dist-packages/psycopg2/__init__.py", line 127, in connect
    conn = _connect(dsn, connection_factory=connection_factory, **kwasync)
psycopg2.OperationalError: could not connect to server: Network is unreachable
	Is the server running on host "192.168.0.235" and accepting
	TCP/IP connections on port 5432?



Traceback (most recent call last):
  File "/home/pi/Desktop/message.py", line 23, in <module>
    conn = psycopg2.connect(database="performance", user='pi', password='Sox2017!', host='192.168.0.235', port= '5432')
  File "/usr/local/lib/python2.7/dist-packages/psycopg2/__init__.py", line 127, in connect
    conn = _connect(dsn, connection_factory=connection_factory, **kwasync)
psycopg2.OperationalError: could not connect to server: Network is unreachable
	Is the server running on host "192.168.0.235" and accepting
	TCP/IP connections on port 5432?



Traceback (most recent call last):
  File "/home/pi/Desktop/message.py", line 23, in <module>
    conn = psycopg2.connect(database="performance", user='pi', password='Sox2017!', host='192.168.0.235', port= '5432')
  File "/usr/local/lib/python2.7/dist-packages/psycopg2/__init__.py", line 127, in connect
    conn = _connect(dsn, connection_factory=connection_factory, **kwasync)
psycopg2.OperationalError: could not connect to server: Network is unreachable
	Is the server running on host "192.168.0.235" and accepting
	TCP/IP connections on port 5432?



Traceback (most recent call last):
  File "/home/pi/Desktop/message.py", line 23, in <module>
    conn = psycopg2.connect(database="performance", user='pi', password='Sox2017!', host='192.168.0.235', port= '5432')
  File "/usr/local/lib/python2.7/dist-packages/psycopg2/__init__.py", line 127, in connect
    conn = _connect(dsn, connection_factory=connection_factory, **kwasync)
psycopg2.OperationalError: could not connect to server: Network is unreachable
	Is the server running on host "192.168.0.235" and accepting
	TCP/IP connections on port 5432?



Traceback (most recent call last):
  File "/home/pi/Desktop/message.py", line 23, in <module>
    conn = psycopg2.connect(database="performance", user='pi', password='Sox2017!', host='192.168.0.235', port= '5432')
  File "/usr/local/lib/python2.7/dist-packages/psycopg2/__init__.py", line 127, in connect
    conn = _connect(dsn, connection_factory=connection_factory, **kwasync)
psycopg2.OperationalError: could not connect to server: Network is unreachable
	Is the server running on host "192.168.0.235" and accepting
	TCP/IP connections on port 5432?



Traceback (most recent call last):
  File "/home/pi/Desktop/message.py", line 23, in <module>
    conn = psycopg2.connect(database="performance", user='pi', password='Sox2017!', host='192.168.0.235', port= '5432')
  File "/usr/local/lib/python2.7/dist-packages/psycopg2/__init__.py", line 127, in connect
    conn = _connect(dsn, connection_factory=connection_factory, **kwasync)
psycopg2.OperationalError: could not connect to server: Network is unreachable
	Is the server running on host "192.168.0.235" and accepting
	TCP/IP connections on port 5432?



Traceback (most recent call last):
  File "/home/pi/Desktop/message.py", line 23, in <module>
    conn = psycopg2.connect(database="performance", user='pi', password='Sox2017!', host='192.168.0.235', port= '5432')
  File "/usr/local/lib/python2.7/dist-packages/psycopg2/__init__.py", line 127, in connect
    conn = _connect(dsn, connection_factory=connection_factory, **kwasync)
psycopg2.OperationalError: could not connect to server: Network is unreachable
	Is the server running on host "192.168.0.235" and accepting
	TCP/IP connections on port 5432?



Traceback (most recent call last):
  File "/home/pi/Desktop/message.py", line 23, in <module>
    conn = psycopg2.connect(database="performance", user='pi', password='Sox2017!', host='192.168.0.235', port= '5432')
  File "/usr/local/lib/python2.7/dist-packages/psycopg2/__init__.py", line 127, in connect
    conn = _connect(dsn, connection_factory=connection_factory, **kwasync)
psycopg2.OperationalError: could not connect to server: Network is unreachable
	Is the server running on host "192.168.0.235" and accepting
	TCP/IP connections on port 5432?



Traceback (most recent call last):
  File "/home/pi/Desktop/message.py", line 23, in <module>
    conn = psycopg2.connect(database="performance", user='pi', password='Sox2017!', host='192.168.0.235', port= '5432')
  File "/usr/local/lib/python2.7/dist-packages/psycopg2/__init__.py", line 127, in connect
    conn = _connect(dsn, connection_factory=connection_factory, **kwasync)
psycopg2.OperationalError: could not connect to server: Network is unreachable
	Is the server running on host "192.168.0.235" and accepting
	TCP/IP connections on port 5432?



Traceback (most recent call last):
  File "/home/pi/Desktop/message.py", line 23, in <module>
    conn = psycopg2.connect(database="performance", user='pi', password='Sox2017!', host='192.168.0.235', port= '5432')
  File "/usr/local/lib/python2.7/dist-packages/psycopg2/__init__.py", line 127, in connect
    conn = _connect(dsn, connection_factory=connection_factory, **kwasync)
psycopg2.OperationalError: could not connect to server: Network is unreachable
	Is the server running on host "192.168.0.235" and accepting
	TCP/IP connections on port 5432?



Traceback (most recent call last):
  File "/home/pi/Desktop/message.py", line 23, in <module>
    conn = psycopg2.connect(database="performance", user='pi', password='Sox2017!', host='192.168.0.235', port= '5432')
  File "/usr/local/lib/python2.7/dist-packages/psycopg2/__init__.py", line 127, in connect
    conn = _connect(dsn, connection_factory=connection_factory, **kwasync)
psycopg2.OperationalError: could not connect to server: Network is unreachable
	Is the server running on host "192.168.0.235" and accepting
	TCP/IP connections on port 5432?



Traceback (most recent call last):
  File "/home/pi/Desktop/message.py", line 23, in <module>
    conn = psycopg2.connect(database="performance", user='pi', password='Sox2017!', host='192.168.0.235', port= '5432')
  File "/usr/local/lib/python2.7/dist-packages/psycopg2/__init__.py", line 127, in connect
    conn = _connect(dsn, connection_factory=connection_factory, **kwasync)
psycopg2.OperationalError: could not connect to server: Network is unreachable
	Is the server running on host "192.168.0.235" and accepting
	TCP/IP connections on port 5432?



Traceback (most recent call last):
  File "/home/pi/Desktop/message.py", line 23, in <module>
    conn = psycopg2.connect(database="performance", user='pi', password='Sox2017!', host='192.168.0.235', port= '5432')
  File "/usr/local/lib/python2.7/dist-packages/psycopg2/__init__.py", line 127, in connect
    conn = _connect(dsn, connection_factory=connection_factory, **kwasync)
psycopg2.OperationalError: could not connect to server: Network is unreachable
	Is the server running on host "192.168.0.235" and accepting
	TCP/IP connections on port 5432?



Traceback (most recent call last):
  File "/home/pi/Desktop/message.py", line 23, in <module>
    conn = psycopg2.connect(database="performance", user='pi', password='Sox2017!', host='192.168.0.235', port= '5432')
  File "/usr/local/lib/python2.7/dist-packages/psycopg2/__init__.py", line 127, in connect
    conn = _connect(dsn, connection_factory=connection_factory, **kwasync)
psycopg2.OperationalError: could not connect to server: Network is unreachable
	Is the server running on host "192.168.0.235" and accepting
	TCP/IP connections on port 5432?



Traceback (most recent call last):
  File "/home/pi/Desktop/message.py", line 23, in <module>
    conn = psycopg2.connect(database="performance", user='pi', password='Sox2017!', host='192.168.0.235', port= '5432')
  File "/usr/local/lib/python2.7/dist-packages/psycopg2/__init__.py", line 127, in connect
    conn = _connect(dsn, connection_factory=connection_factory, **kwasync)
psycopg2.OperationalError: could not connect to server: Network is unreachable
	Is the server running on host "192.168.0.235" and accepting
	TCP/IP connections on port 5432?



Traceback (most recent call last):
  File "/home/pi/Desktop/message.py", line 23, in <module>
    conn = psycopg2.connect(database="performance", user='pi', password='Sox2017!', host='192.168.0.235', port= '5432')
  File "/usr/local/lib/python2.7/dist-packages/psycopg2/__init__.py", line 127, in connect
    conn = _connect(dsn, connection_factory=connection_factory, **kwasync)
psycopg2.OperationalError: could not connect to server: Network is unreachable
	Is the server running on host "192.168.0.235" and accepting
	TCP/IP connections on port 5432?



Traceback (most recent call last):
  File "/home/pi/Desktop/message.py", line 23, in <module>
    conn = psycopg2.connect(database="performance", user='pi', password='Sox2017!', host='192.168.0.235', port= '5432')
  File "/usr/local/lib/python2.7/dist-packages/psycopg2/__init__.py", line 127, in connect
    conn = _connect(dsn, connection_factory=connection_factory, **kwasync)
psycopg2.OperationalError: could not connect to server: Network is unreachable
	Is the server running on host "192.168.0.235" and accepting
	TCP/IP connections on port 5432?



Traceback (most recent call last):
  File "/home/pi/Desktop/message.py", line 23, in <module>
    conn = psycopg2.connect(database="performance", user='pi', password='Sox2017!', host='192.168.0.235', port= '5432')
  File "/usr/local/lib/python2.7/dist-packages/psycopg2/__init__.py", line 127, in connect
    conn = _connect(dsn, connection_factory=connection_factory, **kwasync)
psycopg2.OperationalError: could not connect to server: Network is unreachable
	Is the server running on host "192.168.0.235" and accepting
	TCP/IP connections on port 5432?



Traceback (most recent call last):
  File "/home/pi/Desktop/message.py", line 23, in <module>
    conn = psycopg2.connect(database="performance", user='pi', password='Sox2017!', host='192.168.0.235', port= '5432')
  File "/usr/local/lib/python2.7/dist-packages/psycopg2/__init__.py", line 127, in connect
    conn = _connect(dsn, connection_factory=connection_factory, **kwasync)
psycopg2.OperationalError: could not connect to server: Network is unreachable
	Is the server running on host "192.168.0.235" and accepting
	TCP/IP connections on port 5432?



Traceback (most recent call last):
  File "/home/pi/Desktop/message.py", line 23, in <module>
    conn = psycopg2.connect(database="performance", user='pi', password='Sox2017!', host='192.168.0.235', port= '5432')
  File "/usr/local/lib/python2.7/dist-packages/psycopg2/__init__.py", line 127, in connect
    conn = _connect(dsn, connection_factory=connection_factory, **kwasync)
psycopg2.OperationalError: could not connect to server: Network is unreachable
	Is the server running on host "192.168.0.235" and accepting
	TCP/IP connections on port 5432?



Traceback (most recent call last):
  File "/home/pi/Desktop/message.py", line 23, in <module>
    conn = psycopg2.connect(database="performance", user='pi', password='Sox2017!', host='192.168.0.235', port= '5432')
  File "/usr/local/lib/python2.7/dist-packages/psycopg2/__init__.py", line 127, in connect
    conn = _connect(dsn, connection_factory=connection_factory, **kwasync)
psycopg2.OperationalError: could not connect to server: Network is unreachable
	Is the server running on host "192.168.0.235" and accepting
	TCP/IP connections on port 5432?



Traceback (most recent call last):
  File "/home/pi/Desktop/message.py", line 23, in <module>
    conn = psycopg2.connect(database="performance", user='pi', password='Sox2017!', host='192.168.0.235', port= '5432')
  File "/usr/local/lib/python2.7/dist-packages/psycopg2/__init__.py", line 127, in connect
    conn = _connect(dsn, connection_factory=connection_factory, **kwasync)
psycopg2.OperationalError: could not connect to server: Network is unreachable
	Is the server running on host "192.168.0.235" and accepting
	TCP/IP connections on port 5432?



Traceback (most recent call last):
  File "/home/pi/Desktop/message.py", line 23, in <module>
    conn = psycopg2.connect(database="performance", user='pi', password='Sox2017!', host='192.168.0.235', port= '5432')
  File "/usr/local/lib/python2.7/dist-packages/psycopg2/__init__.py", line 127, in connect
    conn = _connect(dsn, connection_factory=connection_factory, **kwasync)
psycopg2.OperationalError: could not connect to server: Network is unreachable
	Is the server running on host "192.168.0.235" and accepting
	TCP/IP connections on port 5432?



Traceback (most recent call last):
  File "/home/pi/Desktop/message.py", line 23, in <module>
    conn = psycopg2.connect(database="performance", user='pi', password='Sox2017!', host='192.168.0.235', port= '5432')
  File "/usr/local/lib/python2.7/dist-packages/psycopg2/__init__.py", line 127, in connect
    conn = _connect(dsn, connection_factory=connection_factory, **kwasync)
psycopg2.OperationalError: could not connect to server: Network is unreachable
	Is the server running on host "192.168.0.235" and accepting
	TCP/IP connections on port 5432?



Traceback (most recent call last):
  File "/home/pi/Desktop/message.py", line 23, in <module>
    conn = psycopg2.connect(database="performance", user='pi', password='Sox2017!', host='192.168.0.235', port= '5432')
  File "/usr/local/lib/python2.7/dist-packages/psycopg2/__init__.py", line 127, in connect
    conn = _connect(dsn, connection_factory=connection_factory, **kwasync)
psycopg2.OperationalError: could not connect to server: Network is unreachable
	Is the server running on host "192.168.0.235" and accepting
	TCP/IP connections on port 5432?



Traceback (most recent call last):
  File "/home/pi/Desktop/message.py", line 23, in <module>
    conn = psycopg2.connect(database="performance", user='pi', password='Sox2017!', host='192.168.0.235', port= '5432')
  File "/usr/local/lib/python2.7/dist-packages/psycopg2/__init__.py", line 127, in connect
    conn = _connect(dsn, connection_factory=connection_factory, **kwasync)
psycopg2.OperationalError: could not connect to server: Network is unreachable
	Is the server running on host "192.168.0.235" and accepting
	TCP/IP connections on port 5432?



Traceback (most recent call last):
  File "/home/pi/Desktop/message.py", line 23, in <module>
    conn = psycopg2.connect(database="performance", user='pi', password='Sox2017!', host='192.168.0.235', port= '5432')
  File "/usr/local/lib/python2.7/dist-packages/psycopg2/__init__.py", line 127, in connect
    conn = _connect(dsn, connection_factory=connection_factory, **kwasync)
psycopg2.OperationalError: could not connect to server: Network is unreachable
	Is the server running on host "192.168.0.235" and accepting
	TCP/IP connections on port 5432?



Traceback (most recent call last):
  File "/home/pi/Desktop/message.py", line 23, in <module>
    conn = psycopg2.connect(database="performance", user='pi', password='Sox2017!', host='192.168.0.235', port= '5432')
  File "/usr/local/lib/python2.7/dist-packages/psycopg2/__init__.py", line 127, in connect
    conn = _connect(dsn, connection_factory=connection_factory, **kwasync)
psycopg2.OperationalError: could not connect to server: Network is unreachable
	Is the server running on host "192.168.0.235" and accepting
	TCP/IP connections on port 5432?



Traceback (most recent call last):
  File "/home/pi/Desktop/message.py", line 23, in <module>
    conn = psycopg2.connect(database="performance", user='pi', password='Sox2017!', host='192.168.0.235', port= '5432')
  File "/usr/local/lib/python2.7/dist-packages/psycopg2/__init__.py", line 127, in connect
    conn = _connect(dsn, connection_factory=connection_factory, **kwasync)
psycopg2.OperationalError: could not connect to server: No route to host
	Is the server running on host "192.168.0.235" and accepting
	TCP/IP connections on port 5432?



Traceback (most recent call last):
  File "/home/pi/Desktop/message.py", line 23, in <module>
    conn = psycopg2.connect(database="performance", user='pi', password='Sox2017!', host='192.168.0.235', port= '5432')
  File "/usr/local/lib/python2.7/dist-packages/psycopg2/__init__.py", line 127, in connect
    conn = _connect(dsn, connection_factory=connection_factory, **kwasync)
psycopg2.OperationalError: could not connect to server: No route to host
	Is the server running on host "192.168.0.235" and accepting
	TCP/IP connections on port 5432?



Traceback (most recent call last):
  File "/home/pi/Desktop/message.py", line 23, in <module>
    conn = psycopg2.connect(database="performance", user='pi', password='Sox2017!', host='192.168.0.235', port= '5432')
  File "/usr/local/lib/python2.7/dist-packages/psycopg2/__init__.py", line 127, in connect
    conn = _connect(dsn, connection_factory=connection_factory, **kwasync)
psycopg2.OperationalError: could not connect to server: No route to host
	Is the server running on host "192.168.0.235" and accepting
	TCP/IP connections on port 5432?



Traceback (most recent call last):
  File "/home/pi/Desktop/message.py", line 23, in <module>
    conn = psycopg2.connect(database="performance", user='pi', password='Sox2017!', host='192.168.0.235', port= '5432')
  File "/usr/local/lib/python2.7/dist-packages/psycopg2/__init__.py", line 127, in connect
    conn = _connect(dsn, connection_factory=connection_factory, **kwasync)
psycopg2.OperationalError: could not connect to server: No route to host
	Is the server running on host "192.168.0.235" and accepting
	TCP/IP connections on port 5432?



Traceback (most recent call last):
  File "/home/pi/Desktop/message.py", line 23, in <module>
    conn = psycopg2.connect(database="performance", user='pi', password='Sox2017!', host='192.168.0.235', port= '5432')
  File "/usr/local/lib/python2.7/dist-packages/psycopg2/__init__.py", line 127, in connect
    conn = _connect(dsn, connection_factory=connection_factory, **kwasync)
psycopg2.OperationalError: could not connect to server: No route to host
	Is the server running on host "192.168.0.235" and accepting
	TCP/IP connections on port 5432?



Traceback (most recent call last):
  File "/home/pi/Desktop/message.py", line 23, in <module>
    conn = psycopg2.connect(database="performance", user='pi', password='Sox2017!', host='192.168.0.235', port= '5432')
  File "/usr/local/lib/python2.7/dist-packages/psycopg2/__init__.py", line 127, in connect
    conn = _connect(dsn, connection_factory=connection_factory, **kwasync)
psycopg2.OperationalError: could not connect to server: No route to host
	Is the server running on host "192.168.0.235" and accepting
	TCP/IP connections on port 5432?



Traceback (most recent call last):
  File "/home/pi/Desktop/message.py", line 23, in <module>
    conn = psycopg2.connect(database="performance", user='pi', password='Sox2017!', host='192.168.0.235', port= '5432')
  File "/usr/local/lib/python2.7/dist-packages/psycopg2/__init__.py", line 127, in connect
    conn = _connect(dsn, connection_factory=connection_factory, **kwasync)
psycopg2.OperationalError: could not connect to server: No route to host
	Is the server running on host "192.168.0.235" and accepting
	TCP/IP connections on port 5432?



Traceback (most recent call last):
  File "/home/pi/Desktop/message.py", line 23, in <module>
    conn = psycopg2.connect(database="performance", user='pi', password='Sox2017!', host='192.168.0.235', port= '5432')
  File "/usr/local/lib/python2.7/dist-packages/psycopg2/__init__.py", line 127, in connect
    conn = _connect(dsn, connection_factory=connection_factory, **kwasync)
psycopg2.OperationalError: could not connect to server: No route to host
	Is the server running on host "192.168.0.235" and accepting
	TCP/IP connections on port 5432?



Traceback (most recent call last):
  File "/home/pi/Desktop/message.py", line 23, in <module>
    conn = psycopg2.connect(database="performance", user='pi', password='Sox2017!', host='192.168.0.235', port= '5432')
  File "/usr/local/lib/python2.7/dist-packages/psycopg2/__init__.py", line 127, in connect
    conn = _connect(dsn, connection_factory=connection_factory, **kwasync)
psycopg2.OperationalError: could not connect to server: No route to host
	Is the server running on host "192.168.0.235" and accepting
	TCP/IP connections on port 5432?



Traceback (most recent call last):
  File "/home/pi/Desktop/message.py", line 23, in <module>
    conn = psycopg2.connect(database="performance", user='pi', password='Sox2017!', host='192.168.0.235', port= '5432')
  File "/usr/local/lib/python2.7/dist-packages/psycopg2/__init__.py", line 127, in connect
    conn = _connect(dsn, connection_factory=connection_factory, **kwasync)
psycopg2.OperationalError: could not connect to server: No route to host
	Is the server running on host "192.168.0.235" and accepting
	TCP/IP connections on port 5432?



Traceback (most recent call last):
  File "/home/pi/Desktop/message.py", line 23, in <module>
    conn = psycopg2.connect(database="performance", user='pi', password='Sox2017!', host='192.168.0.235', port= '5432')
  File "/usr/local/lib/python2.7/dist-packages/psycopg2/__init__.py", line 127, in connect
    conn = _connect(dsn, connection_factory=connection_factory, **kwasync)
psycopg2.OperationalError: could not connect to server: No route to host
	Is the server running on host "192.168.0.235" and accepting
	TCP/IP connections on port 5432?



Traceback (most recent call last):
  File "/home/pi/Desktop/message.py", line 23, in <module>
    conn = psycopg2.connect(database="performance", user='pi', password='Sox2017!', host='192.168.0.235', port= '5432')
  File "/usr/local/lib/python2.7/dist-packages/psycopg2/__init__.py", line 127, in connect
    conn = _connect(dsn, connection_factory=connection_factory, **kwasync)
psycopg2.OperationalError: could not connect to server: No route to host
	Is the server running on host "192.168.0.235" and accepting
	TCP/IP connections on port 5432?



Traceback (most recent call last):
  File "/home/pi/Desktop/message.py", line 23, in <module>
    conn = psycopg2.connect(database="performance", user='pi', password='Sox2017!', host='192.168.0.235', port= '5432')
  File "/usr/local/lib/python2.7/dist-packages/psycopg2/__init__.py", line 127, in connect
    conn = _connect(dsn, connection_factory=connection_factory, **kwasync)
psycopg2.OperationalError: could not connect to server: No route to host
	Is the server running on host "192.168.0.235" and accepting
	TCP/IP connections on port 5432?



Traceback (most recent call last):
  File "/home/pi/Desktop/message.py", line 23, in <module>
    conn = psycopg2.connect(database="performance", user='pi', password='Sox2017!', host='192.168.0.235', port= '5432')
  File "/usr/local/lib/python2.7/dist-packages/psycopg2/__init__.py", line 127, in connect
    conn = _connect(dsn, connection_factory=connection_factory, **kwasync)
psycopg2.OperationalError: could not connect to server: No route to host
	Is the server running on host "192.168.0.235" and accepting
	TCP/IP connections on port 5432?



Traceback (most recent call last):
  File "/home/pi/Desktop/message.py", line 23, in <module>
    conn = psycopg2.connect(database="performance", user='pi', password='Sox2017!', host='192.168.0.235', port= '5432')
  File "/usr/local/lib/python2.7/dist-packages/psycopg2/__init__.py", line 127, in connect
    conn = _connect(dsn, connection_factory=connection_factory, **kwasync)
psycopg2.OperationalError: could not connect to server: No route to host
	Is the server running on host "192.168.0.235" and accepting
	TCP/IP connections on port 5432?



Traceback (most recent call last):
  File "/home/pi/Desktop/message.py", line 23, in <module>
    conn = psycopg2.connect(database="performance", user='pi', password='Sox2017!', host='192.168.0.235', port= '5432')
  File "/usr/local/lib/python2.7/dist-packages/psycopg2/__init__.py", line 127, in connect
    conn = _connect(dsn, connection_factory=connection_factory, **kwasync)
psycopg2.OperationalError: could not connect to server: No route to host
	Is the server running on host "192.168.0.235" and accepting
	TCP/IP connections on port 5432?



Traceback (most recent call last):
  File "/home/pi/Desktop/message.py", line 23, in <module>
    conn = psycopg2.connect(database="performance", user='pi', password='Sox2017!', host='192.168.0.235', port= '5432')
  File "/usr/local/lib/python2.7/dist-packages/psycopg2/__init__.py", line 127, in connect
    conn = _connect(dsn, connection_factory=connection_factory, **kwasync)
psycopg2.OperationalError: could not connect to server: No route to host
	Is the server running on host "192.168.0.235" and accepting
	TCP/IP connections on port 5432?



Traceback (most recent call last):
  File "/home/pi/Desktop/message.py", line 23, in <module>
    conn = psycopg2.connect(database="performance", user='pi', password='Sox2017!', host='192.168.0.235', port= '5432')
  File "/usr/local/lib/python2.7/dist-packages/psycopg2/__init__.py", line 127, in connect
    conn = _connect(dsn, connection_factory=connection_factory, **kwasync)
psycopg2.OperationalError: could not connect to server: No route to host
	Is the server running on host "192.168.0.235" and accepting
	TCP/IP connections on port 5432?



Traceback (most recent call last):
  File "/home/pi/Desktop/message.py", line 23, in <module>
    conn = psycopg2.connect(database="performance", user='pi', password='Sox2017!', host='192.168.0.235', port= '5432')
  File "/usr/local/lib/python2.7/dist-packages/psycopg2/__init__.py", line 127, in connect
    conn = _connect(dsn, connection_factory=connection_factory, **kwasync)
psycopg2.OperationalError: could not connect to server: No route to host
	Is the server running on host "192.168.0.235" and accepting
	TCP/IP connections on port 5432?



Traceback (most recent call last):
  File "/home/pi/Desktop/message.py", line 23, in <module>
    conn = psycopg2.connect(database="performance", user='pi', password='Sox2017!', host='192.168.0.235', port= '5432')
  File "/usr/local/lib/python2.7/dist-packages/psycopg2/__init__.py", line 127, in connect
    conn = _connect(dsn, connection_factory=connection_factory, **kwasync)
psycopg2.OperationalError: could not connect to server: No route to host
	Is the server running on host "192.168.0.235" and accepting
	TCP/IP connections on port 5432?



Traceback (most recent call last):
  File "/home/pi/Desktop/message.py", line 23, in <module>
    conn = psycopg2.connect(database="performance", user='pi', password='Sox2017!', host='192.168.0.235', port= '5432')
  File "/usr/local/lib/python2.7/dist-packages/psycopg2/__init__.py", line 127, in connect
    conn = _connect(dsn, connection_factory=connection_factory, **kwasync)
psycopg2.OperationalError: could not connect to server: Network is unreachable
	Is the server running on host "192.168.0.235" and accepting
	TCP/IP connections on port 5432?



Traceback (most recent call last):
  File "/home/pi/Desktop/message.py", line 23, in <module>
    conn = psycopg2.connect(database="performance", user='pi', password='Sox2017!', host='192.168.0.235', port= '5432')
  File "/usr/local/lib/python2.7/dist-packages/psycopg2/__init__.py", line 127, in connect
    conn = _connect(dsn, connection_factory=connection_factory, **kwasync)
psycopg2.OperationalError: could not connect to server: Network is unreachable
	Is the server running on host "192.168.0.235" and accepting
	TCP/IP connections on port 5432?



Traceback (most recent call last):
  File "/home/pi/Desktop/message.py", line 23, in <module>
    conn = psycopg2.connect(database="performance", user='pi', password='Sox2017!', host='192.168.0.235', port= '5432')
  File "/usr/local/lib/python2.7/dist-packages/psycopg2/__init__.py", line 127, in connect
    conn = _connect(dsn, connection_factory=connection_factory, **kwasync)
psycopg2.OperationalError: could not connect to server: Network is unreachable
	Is the server running on host "192.168.0.235" and accepting
	TCP/IP connections on port 5432?



Traceback (most recent call last):
  File "/home/pi/Desktop/message.py", line 23, in <module>
    conn = psycopg2.connect(database="performance", user='pi', password='Sox2017!', host='192.168.0.235', port= '5432')
  File "/usr/local/lib/python2.7/dist-packages/psycopg2/__init__.py", line 127, in connect
    conn = _connect(dsn, connection_factory=connection_factory, **kwasync)
psycopg2.OperationalError: could not connect to server: Network is unreachable
	Is the server running on host "192.168.0.235" and accepting
	TCP/IP connections on port 5432?



Traceback (most recent call last):
  File "/home/pi/Desktop/message.py", line 23, in <module>
    conn = psycopg2.connect(database="performance", user='pi', password='Sox2017!', host='192.168.0.235', port= '5432')
  File "/usr/local/lib/python2.7/dist-packages/psycopg2/__init__.py", line 127, in connect
    conn = _connect(dsn, connection_factory=connection_factory, **kwasync)
psycopg2.OperationalError: could not connect to server: Network is unreachable
	Is the server running on host "192.168.0.235" and accepting
	TCP/IP connections on port 5432?



Traceback (most recent call last):
  File "/home/pi/Desktop/message.py", line 23, in <module>
    conn = psycopg2.connect(database="performance", user='pi', password='Sox2017!', host='192.168.0.235', port= '5432')
  File "/usr/local/lib/python2.7/dist-packages/psycopg2/__init__.py", line 127, in connect
    conn = _connect(dsn, connection_factory=connection_factory, **kwasync)
psycopg2.OperationalError: could not connect to server: Network is unreachable
	Is the server running on host "192.168.0.235" and accepting
	TCP/IP connections on port 5432?



Traceback (most recent call last):
  File "/home/pi/Desktop/message.py", line 23, in <module>
    conn = psycopg2.connect(database="performance", user='pi', password='Sox2017!', host='192.168.0.235', port= '5432')
  File "/usr/local/lib/python2.7/dist-packages/psycopg2/__init__.py", line 127, in connect
    conn = _connect(dsn, connection_factory=connection_factory, **kwasync)
psycopg2.OperationalError: could not connect to server: Network is unreachable
	Is the server running on host "192.168.0.235" and accepting
	TCP/IP connections on port 5432?



Traceback (most recent call last):
  File "/home/pi/Desktop/message.py", line 23, in <module>
    conn = psycopg2.connect(database="performance", user='pi', password='Sox2017!', host='192.168.0.235', port= '5432')
  File "/usr/local/lib/python2.7/dist-packages/psycopg2/__init__.py", line 127, in connect
    conn = _connect(dsn, connection_factory=connection_factory, **kwasync)
psycopg2.OperationalError: could not connect to server: Network is unreachable
	Is the server running on host "192.168.0.235" and accepting
	TCP/IP connections on port 5432?



Traceback (most recent call last):
  File "/home/pi/Desktop/message.py", line 23, in <module>
    conn = psycopg2.connect(database="performance", user='pi', password='Sox2017!', host='192.168.0.235', port= '5432')
  File "/usr/local/lib/python2.7/dist-packages/psycopg2/__init__.py", line 127, in connect
    conn = _connect(dsn, connection_factory=connection_factory, **kwasync)
psycopg2.OperationalError: could not connect to server: Network is unreachable
	Is the server running on host "192.168.0.235" and accepting
	TCP/IP connections on port 5432?



Traceback (most recent call last):
  File "/home/pi/Desktop/message.py", line 23, in <module>
    conn = psycopg2.connect(database="performance", user='pi', password='Sox2017!', host='192.168.0.235', port= '5432')
  File "/usr/local/lib/python2.7/dist-packages/psycopg2/__init__.py", line 127, in connect
    conn = _connect(dsn, connection_factory=connection_factory, **kwasync)
psycopg2.OperationalError: could not connect to server: Network is unreachable
	Is the server running on host "192.168.0.235" and accepting
	TCP/IP connections on port 5432?



Traceback (most recent call last):
  File "/home/pi/Desktop/message.py", line 23, in <module>
    conn = psycopg2.connect(database="performance", user='pi', password='Sox2017!', host='192.168.0.235', port= '5432')
  File "/usr/local/lib/python2.7/dist-packages/psycopg2/__init__.py", line 127, in connect
    conn = _connect(dsn, connection_factory=connection_factory, **kwasync)
psycopg2.OperationalError: could not connect to server: Network is unreachable
	Is the server running on host "192.168.0.235" and accepting
	TCP/IP connections on port 5432?



Traceback (most recent call last):
  File "/home/pi/Desktop/message.py", line 23, in <module>
    conn = psycopg2.connect(database="performance", user='pi', password='Sox2017!', host='192.168.0.235', port= '5432')
  File "/usr/local/lib/python2.7/dist-packages/psycopg2/__init__.py", line 127, in connect
    conn = _connect(dsn, connection_factory=connection_factory, **kwasync)
psycopg2.OperationalError: could not connect to server: Network is unreachable
	Is the server running on host "192.168.0.235" and accepting
	TCP/IP connections on port 5432?



Traceback (most recent call last):
  File "/home/pi/Desktop/message.py", line 23, in <module>
    conn = psycopg2.connect(database="performance", user='pi', password='Sox2017!', host='192.168.0.235', port= '5432')
  File "/usr/local/lib/python2.7/dist-packages/psycopg2/__init__.py", line 127, in connect
    conn = _connect(dsn, connection_factory=connection_factory, **kwasync)
psycopg2.OperationalError: could not connect to server: Network is unreachable
	Is the server running on host "192.168.0.235" and accepting
	TCP/IP connections on port 5432?



Traceback (most recent call last):
  File "/home/pi/Desktop/message.py", line 23, in <module>
    conn = psycopg2.connect(database="performance", user='pi', password='Sox2017!', host='192.168.0.235', port= '5432')
  File "/usr/local/lib/python2.7/dist-packages/psycopg2/__init__.py", line 127, in connect
    conn = _connect(dsn, connection_factory=connection_factory, **kwasync)
psycopg2.OperationalError: could not connect to server: Network is unreachable
	Is the server running on host "192.168.0.235" and accepting
	TCP/IP connections on port 5432?



Traceback (most recent call last):
  File "/home/pi/Desktop/message.py", line 23, in <module>
    conn = psycopg2.connect(database="performance", user='pi', password='Sox2017!', host='192.168.0.235', port= '5432')
  File "/usr/local/lib/python2.7/dist-packages/psycopg2/__init__.py", line 127, in connect
    conn = _connect(dsn, connection_factory=connection_factory, **kwasync)
psycopg2.OperationalError: could not connect to server: Network is unreachable
	Is the server running on host "192.168.0.235" and accepting
	TCP/IP connections on port 5432?



Traceback (most recent call last):
  File "/home/pi/Desktop/message.py", line 23, in <module>
    conn = psycopg2.connect(database="performance", user='pi', password='Sox2017!', host='192.168.0.235', port= '5432')
  File "/usr/local/lib/python2.7/dist-packages/psycopg2/__init__.py", line 127, in connect
    conn = _connect(dsn, connection_factory=connection_factory, **kwasync)
psycopg2.OperationalError: could not connect to server: Network is unreachable
	Is the server running on host "192.168.0.235" and accepting
	TCP/IP connections on port 5432?



Traceback (most recent call last):
  File "/home/pi/Desktop/message.py", line 23, in <module>
    conn = psycopg2.connect(database="performance", user='pi', password='Sox2017!', host='192.168.0.235', port= '5432')
  File "/usr/local/lib/python2.7/dist-packages/psycopg2/__init__.py", line 127, in connect
    conn = _connect(dsn, connection_factory=connection_factory, **kwasync)
psycopg2.OperationalError: could not connect to server: Network is unreachable
	Is the server running on host "192.168.0.235" and accepting
	TCP/IP connections on port 5432?



Traceback (most recent call last):
  File "/home/pi/Desktop/message.py", line 23, in <module>
    conn = psycopg2.connect(database="performance", user='pi', password='Sox2017!', host='192.168.0.235', port= '5432')
  File "/usr/local/lib/python2.7/dist-packages/psycopg2/__init__.py", line 127, in connect
    conn = _connect(dsn, connection_factory=connection_factory, **kwasync)
psycopg2.OperationalError: could not connect to server: Network is unreachable
	Is the server running on host "192.168.0.235" and accepting
	TCP/IP connections on port 5432?



Traceback (most recent call last):
  File "/home/pi/Desktop/message.py", line 23, in <module>
    conn = psycopg2.connect(database="performance", user='pi', password='Sox2017!', host='192.168.0.235', port= '5432')
  File "/usr/local/lib/python2.7/dist-packages/psycopg2/__init__.py", line 127, in connect
    conn = _connect(dsn, connection_factory=connection_factory, **kwasync)
psycopg2.OperationalError: could not connect to server: Network is unreachable
	Is the server running on host "192.168.0.235" and accepting
	TCP/IP connections on port 5432?



Traceback (most recent call last):
  File "/home/pi/Desktop/message.py", line 23, in <module>
    conn = psycopg2.connect(database="performance", user='pi', password='Sox2017!', host='192.168.0.235', port= '5432')
  File "/usr/local/lib/python2.7/dist-packages/psycopg2/__init__.py", line 127, in connect
    conn = _connect(dsn, connection_factory=connection_factory, **kwasync)
psycopg2.OperationalError: could not connect to server: Network is unreachable
	Is the server running on host "192.168.0.235" and accepting
	TCP/IP connections on port 5432?



Traceback (most recent call last):
  File "/home/pi/Desktop/message.py", line 23, in <module>
    conn = psycopg2.connect(database="performance", user='pi', password='Sox2017!', host='192.168.0.235', port= '5432')
  File "/usr/local/lib/python2.7/dist-packages/psycopg2/__init__.py", line 127, in connect
    conn = _connect(dsn, connection_factory=connection_factory, **kwasync)
psycopg2.OperationalError: could not connect to server: Network is unreachable
	Is the server running on host "192.168.0.235" and accepting
	TCP/IP connections on port 5432?



Traceback (most recent call last):
  File "/home/pi/Desktop/message.py", line 23, in <module>
    conn = psycopg2.connect(database="performance", user='pi', password='Sox2017!', host='192.168.0.235', port= '5432')
  File "/usr/local/lib/python2.7/dist-packages/psycopg2/__init__.py", line 127, in connect
    conn = _connect(dsn, connection_factory=connection_factory, **kwasync)
psycopg2.OperationalError: could not connect to server: No route to host
	Is the server running on host "192.168.0.235" and accepting
	TCP/IP connections on port 5432?



Traceback (most recent call last):
  File "/home/pi/Desktop/message.py", line 23, in <module>
    conn = psycopg2.connect(database="performance", user='pi', password='Sox2017!', host='192.168.0.235', port= '5432')
  File "/usr/local/lib/python2.7/dist-packages/psycopg2/__init__.py", line 127, in connect
    conn = _connect(dsn, connection_factory=connection_factory, **kwasync)
psycopg2.OperationalError: could not connect to server: No route to host
	Is the server running on host "192.168.0.235" and accepting
	TCP/IP connections on port 5432?



Traceback (most recent call last):
  File "/home/pi/Desktop/message.py", line 23, in <module>
    conn = psycopg2.connect(database="performance", user='pi', password='Sox2017!', host='192.168.0.235', port= '5432')
  File "/usr/local/lib/python2.7/dist-packages/psycopg2/__init__.py", line 127, in connect
    conn = _connect(dsn, connection_factory=connection_factory, **kwasync)
psycopg2.OperationalError: could not connect to server: No route to host
	Is the server running on host "192.168.0.235" and accepting
	TCP/IP connections on port 5432?



Traceback (most recent call last):
  File "/home/pi/Desktop/message.py", line 23, in <module>
    conn = psycopg2.connect(database="performance", user='pi', password='Sox2017!', host='192.168.0.235', port= '5432')
  File "/usr/local/lib/python2.7/dist-packages/psycopg2/__init__.py", line 127, in connect
    conn = _connect(dsn, connection_factory=connection_factory, **kwasync)
psycopg2.OperationalError: could not connect to server: No route to host
	Is the server running on host "192.168.0.235" and accepting
	TCP/IP connections on port 5432?



Traceback (most recent call last):
  File "/home/pi/Desktop/message.py", line 23, in <module>
    conn = psycopg2.connect(database="performance", user='pi', password='Sox2017!', host='192.168.0.235', port= '5432')
  File "/usr/local/lib/python2.7/dist-packages/psycopg2/__init__.py", line 127, in connect
    conn = _connect(dsn, connection_factory=connection_factory, **kwasync)
psycopg2.OperationalError: could not connect to server: No route to host
	Is the server running on host "192.168.0.235" and accepting
	TCP/IP connections on port 5432?



Traceback (most recent call last):
  File "/home/pi/Desktop/message.py", line 23, in <module>
    conn = psycopg2.connect(database="performance", user='pi', password='Sox2017!', host='192.168.0.235', port= '5432')
  File "/usr/local/lib/python2.7/dist-packages/psycopg2/__init__.py", line 127, in connect
    conn = _connect(dsn, connection_factory=connection_factory, **kwasync)
psycopg2.OperationalError: could not connect to server: No route to host
	Is the server running on host "192.168.0.235" and accepting
	TCP/IP connections on port 5432?



Traceback (most recent call last):
  File "/home/pi/Desktop/message.py", line 23, in <module>
    conn = psycopg2.connect(database="performance", user='pi', password='Sox2017!', host='192.168.0.235', port= '5432')
  File "/usr/local/lib/python2.7/dist-packages/psycopg2/__init__.py", line 127, in connect
    conn = _connect(dsn, connection_factory=connection_factory, **kwasync)
psycopg2.OperationalError: could not connect to server: No route to host
	Is the server running on host "192.168.0.235" and accepting
	TCP/IP connections on port 5432?



Traceback (most recent call last):
  File "/home/pi/Desktop/message.py", line 23, in <module>
    conn = psycopg2.connect(database="performance", user='pi', password='Sox2017!', host='192.168.0.235', port= '5432')
  File "/usr/local/lib/python2.7/dist-packages/psycopg2/__init__.py", line 127, in connect
    conn = _connect(dsn, connection_factory=connection_factory, **kwasync)
psycopg2.OperationalError: could not connect to server: No route to host
	Is the server running on host "192.168.0.235" and accepting
	TCP/IP connections on port 5432?



Traceback (most recent call last):
  File "/home/pi/Desktop/message.py", line 23, in <module>
    conn = psycopg2.connect(database="performance", user='pi', password='Sox2017!', host='192.168.0.235', port= '5432')
  File "/usr/local/lib/python2.7/dist-packages/psycopg2/__init__.py", line 127, in connect
    conn = _connect(dsn, connection_factory=connection_factory, **kwasync)
psycopg2.OperationalError: could not connect to server: No route to host
	Is the server running on host "192.168.0.235" and accepting
	TCP/IP connections on port 5432?



Traceback (most recent call last):
  File "/home/pi/Desktop/message.py", line 23, in <module>
    conn = psycopg2.connect(database="performance", user='pi', password='Sox2017!', host='192.168.0.235', port= '5432')
  File "/usr/local/lib/python2.7/dist-packages/psycopg2/__init__.py", line 127, in connect
    conn = _connect(dsn, connection_factory=connection_factory, **kwasync)
psycopg2.OperationalError: could not connect to server: No route to host
	Is the server running on host "192.168.0.235" and accepting
	TCP/IP connections on port 5432?



Traceback (most recent call last):
  File "/home/pi/Desktop/message.py", line 23, in <module>
    conn = psycopg2.connect(database="performance", user='pi', password='Sox2017!', host='192.168.0.235', port= '5432')
  File "/usr/local/lib/python2.7/dist-packages/psycopg2/__init__.py", line 127, in connect
    conn = _connect(dsn, connection_factory=connection_factory, **kwasync)
psycopg2.OperationalError: could not connect to server: No route to host
	Is the server running on host "192.168.0.235" and accepting
	TCP/IP connections on port 5432?



Traceback (most recent call last):
  File "/home/pi/Desktop/message.py", line 23, in <module>
    conn = psycopg2.connect(database="performance", user='pi', password='Sox2017!', host='192.168.0.235', port= '5432')
  File "/usr/local/lib/python2.7/dist-packages/psycopg2/__init__.py", line 127, in connect
    conn = _connect(dsn, connection_factory=connection_factory, **kwasync)
psycopg2.OperationalError: could not connect to server: No route to host
	Is the server running on host "192.168.0.235" and accepting
	TCP/IP connections on port 5432?



Traceback (most recent call last):
  File "/home/pi/Desktop/message.py", line 23, in <module>
    conn = psycopg2.connect(database="performance", user='pi', password='Sox2017!', host='192.168.0.235', port= '5432')
  File "/usr/local/lib/python2.7/dist-packages/psycopg2/__init__.py", line 127, in connect
    conn = _connect(dsn, connection_factory=connection_factory, **kwasync)
psycopg2.OperationalError: could not connect to server: No route to host
	Is the server running on host "192.168.0.235" and accepting
	TCP/IP connections on port 5432?



Traceback (most recent call last):
  File "/home/pi/Desktop/message.py", line 23, in <module>
    conn = psycopg2.connect(database="performance", user='pi', password='Sox2017!', host='192.168.0.235', port= '5432')
  File "/usr/local/lib/python2.7/dist-packages/psycopg2/__init__.py", line 127, in connect
    conn = _connect(dsn, connection_factory=connection_factory, **kwasync)
psycopg2.OperationalError: could not connect to server: No route to host
	Is the server running on host "192.168.0.235" and accepting
	TCP/IP connections on port 5432?



Traceback (most recent call last):
  File "/home/pi/Desktop/message.py", line 23, in <module>
    conn = psycopg2.connect(database="performance", user='pi', password='Sox2017!', host='192.168.0.235', port= '5432')
  File "/usr/local/lib/python2.7/dist-packages/psycopg2/__init__.py", line 127, in connect
    conn = _connect(dsn, connection_factory=connection_factory, **kwasync)
psycopg2.OperationalError: could not connect to server: No route to host
	Is the server running on host "192.168.0.235" and accepting
	TCP/IP connections on port 5432?



Traceback (most recent call last):
  File "/home/pi/Desktop/message.py", line 23, in <module>
    conn = psycopg2.connect(database="performance", user='pi', password='Sox2017!', host='192.168.0.235', port= '5432')
  File "/usr/local/lib/python2.7/dist-packages/psycopg2/__init__.py", line 127, in connect
    conn = _connect(dsn, connection_factory=connection_factory, **kwasync)
psycopg2.OperationalError: could not connect to server: No route to host
	Is the server running on host "192.168.0.235" and accepting
	TCP/IP connections on port 5432?



Traceback (most recent call last):
  File "/home/pi/Desktop/message.py", line 23, in <module>
    conn = psycopg2.connect(database="performance", user='pi', password='Sox2017!', host='192.168.0.235', port= '5432')
  File "/usr/local/lib/python2.7/dist-packages/psycopg2/__init__.py", line 127, in connect
    conn = _connect(dsn, connection_factory=connection_factory, **kwasync)
psycopg2.OperationalError: could not connect to server: Network is unreachable
	Is the server running on host "192.168.0.235" and accepting
	TCP/IP connections on port 5432?



Traceback (most recent call last):
  File "/home/pi/Desktop/message.py", line 23, in <module>
    conn = psycopg2.connect(database="performance", user='pi', password='Sox2017!', host='192.168.0.235', port= '5432')
  File "/usr/local/lib/python2.7/dist-packages/psycopg2/__init__.py", line 127, in connect
    conn = _connect(dsn, connection_factory=connection_factory, **kwasync)
psycopg2.OperationalError: could not connect to server: No route to host
	Is the server running on host "192.168.0.235" and accepting
	TCP/IP connections on port 5432?



Traceback (most recent call last):
  File "/home/pi/Desktop/message.py", line 23, in <module>
    conn = psycopg2.connect(database="performance", user='pi', password='Sox2017!', host='192.168.0.235', port= '5432')
  File "/usr/local/lib/python2.7/dist-packages/psycopg2/__init__.py", line 127, in connect
    conn = _connect(dsn, connection_factory=connection_factory, **kwasync)
psycopg2.OperationalError: could not connect to server: Network is unreachable
	Is the server running on host "192.168.0.235" and accepting
	TCP/IP connections on port 5432?



Traceback (most recent call last):
  File "/home/pi/Desktop/message.py", line 23, in <module>
    conn = psycopg2.connect(database="performance", user='pi', password='Sox2017!', host='192.168.0.235', port= '5432')
  File "/usr/local/lib/python2.7/dist-packages/psycopg2/__init__.py", line 127, in connect
    conn = _connect(dsn, connection_factory=connection_factory, **kwasync)
psycopg2.OperationalError: could not connect to server: Network is unreachable
	Is the server running on host "192.168.0.235" and accepting
	TCP/IP connections on port 5432?



Traceback (most recent call last):
  File "/home/pi/Desktop/message.py", line 23, in <module>
    conn = psycopg2.connect(database="performance", user='pi', password='Sox2017!', host='192.168.0.235', port= '5432')
  File "/usr/local/lib/python2.7/dist-packages/psycopg2/__init__.py", line 127, in connect
    conn = _connect(dsn, connection_factory=connection_factory, **kwasync)
psycopg2.OperationalError: could not connect to server: No route to host
	Is the server running on host "192.168.0.235" and accepting
	TCP/IP connections on port 5432?



Traceback (most recent call last):
  File "/home/pi/Desktop/message.py", line 23, in <module>
    conn = psycopg2.connect(database="performance", user='pi', password='Sox2017!', host='192.168.0.235', port= '5432')
  File "/usr/local/lib/python2.7/dist-packages/psycopg2/__init__.py", line 127, in connect
    conn = _connect(dsn, connection_factory=connection_factory, **kwasync)
psycopg2.OperationalError: could not connect to server: Network is unreachable
	Is the server running on host "192.168.0.235" and accepting
	TCP/IP connections on port 5432?



Traceback (most recent call last):
  File "/home/pi/Desktop/message.py", line 23, in <module>
    conn = psycopg2.connect(database="performance", user='pi', password='Sox2017!', host='192.168.0.235', port= '5432')
  File "/usr/local/lib/python2.7/dist-packages/psycopg2/__init__.py", line 127, in connect
    conn = _connect(dsn, connection_factory=connection_factory, **kwasync)
psycopg2.OperationalError: could not connect to server: Network is unreachable
	Is the server running on host "192.168.0.235" and accepting
	TCP/IP connections on port 5432?



Traceback (most recent call last):
  File "/home/pi/Desktop/message.py", line 23, in <module>
    conn = psycopg2.connect(database="performance", user='pi', password='Sox2017!', host='192.168.0.235', port= '5432')
  File "/usr/local/lib/python2.7/dist-packages/psycopg2/__init__.py", line 127, in connect
    conn = _connect(dsn, connection_factory=connection_factory, **kwasync)
psycopg2.OperationalError: could not connect to server: Connection timed out
	Is the server running on host "192.168.0.235" and accepting
	TCP/IP connections on port 5432?



Traceback (most recent call last):
  File "/home/pi/Desktop/message.py", line 23, in <module>
    conn = psycopg2.connect(database="performance", user='pi', password='Sox2017!', host='192.168.0.235', port= '5432')
  File "/usr/local/lib/python2.7/dist-packages/psycopg2/__init__.py", line 127, in connect
    conn = _connect(dsn, connection_factory=connection_factory, **kwasync)
psycopg2.OperationalError: could not connect to server: Connection timed out
	Is the server running on host "192.168.0.235" and accepting
	TCP/IP connections on port 5432?



Traceback (most recent call last):
  File "/home/pi/Desktop/message.py", line 23, in <module>
    conn = psycopg2.connect(database="performance", user='pi', password='Sox2017!', host='192.168.0.235', port= '5432')
  File "/usr/local/lib/python2.7/dist-packages/psycopg2/__init__.py", line 127, in connect
    conn = _connect(dsn, connection_factory=connection_factory, **kwasync)
psycopg2.OperationalError: could not connect to server: Connection timed out
	Is the server running on host "192.168.0.235" and accepting
	TCP/IP connections on port 5432?



Traceback (most recent call last):
  File "/home/pi/Desktop/message.py", line 23, in <module>
    conn = psycopg2.connect(database="performance", user='pi', password='Sox2017!', host='192.168.0.235', port= '5432')
  File "/usr/local/lib/python2.7/dist-packages/psycopg2/__init__.py", line 127, in connect
    conn = _connect(dsn, connection_factory=connection_factory, **kwasync)
psycopg2.OperationalError: could not connect to server: Connection timed out
	Is the server running on host "192.168.0.235" and accepting
	TCP/IP connections on port 5432?



Traceback (most recent call last):
  File "/home/pi/Desktop/message.py", line 23, in <module>
    conn = psycopg2.connect(database="performance", user='pi', password='Sox2017!', host='192.168.0.235', port= '5432')
  File "/usr/local/lib/python2.7/dist-packages/psycopg2/__init__.py", line 127, in connect
    conn = _connect(dsn, connection_factory=connection_factory, **kwasync)
psycopg2.OperationalError: could not connect to server: Connection timed out
	Is the server running on host "192.168.0.235" and accepting
	TCP/IP connections on port 5432?



Traceback (most recent call last):
  File "/home/pi/Desktop/message.py", line 23, in <module>
    conn = psycopg2.connect(database="performance", user='pi', password='Sox2017!', host='192.168.0.235', port= '5432')
  File "/usr/local/lib/python2.7/dist-packages/psycopg2/__init__.py", line 127, in connect
    conn = _connect(dsn, connection_factory=connection_factory, **kwasync)
psycopg2.OperationalError: could not connect to server: Connection timed out
	Is the server running on host "192.168.0.235" and accepting
	TCP/IP connections on port 5432?



Traceback (most recent call last):
  File "/home/pi/Desktop/message.py", line 23, in <module>
    conn = psycopg2.connect(database="performance", user='pi', password='Sox2017!', host='192.168.0.235', port= '5432')
  File "/usr/local/lib/python2.7/dist-packages/psycopg2/__init__.py", line 127, in connect
    conn = _connect(dsn, connection_factory=connection_factory, **kwasync)
psycopg2.OperationalError: could not connect to server: Connection timed out
	Is the server running on host "192.168.0.235" and accepting
	TCP/IP connections on port 5432?



Traceback (most recent call last):
  File "/home/pi/Desktop/message.py", line 23, in <module>
    conn = psycopg2.connect(database="performance", user='pi', password='Sox2017!', host='192.168.0.235', port= '5432')
  File "/usr/local/lib/python2.7/dist-packages/psycopg2/__init__.py", line 127, in connect
    conn = _connect(dsn, connection_factory=connection_factory, **kwasync)
psycopg2.OperationalError: could not connect to server: Connection timed out
	Is the server running on host "192.168.0.235" and accepting
	TCP/IP connections on port 5432?



Traceback (most recent call last):
  File "/home/pi/Desktop/message.py", line 23, in <module>
    conn = psycopg2.connect(database="performance", user='pi', password='Sox2017!', host='192.168.0.235', port= '5432')
  File "/usr/local/lib/python2.7/dist-packages/psycopg2/__init__.py", line 127, in connect
    conn = _connect(dsn, connection_factory=connection_factory, **kwasync)
psycopg2.OperationalError: could not connect to server: Connection timed out
	Is the server running on host "192.168.0.235" and accepting
	TCP/IP connections on port 5432?



Traceback (most recent call last):
  File "/home/pi/Desktop/message.py", line 23, in <module>
    conn = psycopg2.connect(database="performance", user='pi', password='Sox2017!', host='192.168.0.235', port= '5432')
  File "/usr/local/lib/python2.7/dist-packages/psycopg2/__init__.py", line 127, in connect
    conn = _connect(dsn, connection_factory=connection_factory, **kwasync)
psycopg2.OperationalError: could not connect to server: Connection timed out
	Is the server running on host "192.168.0.235" and accepting
	TCP/IP connections on port 5432?



Traceback (most recent call last):
  File "/home/pi/Desktop/message.py", line 23, in <module>
    conn = psycopg2.connect(database="performance", user='pi', password='Sox2017!', host='192.168.0.235', port= '5432')
  File "/usr/local/lib/python2.7/dist-packages/psycopg2/__init__.py", line 127, in connect
    conn = _connect(dsn, connection_factory=connection_factory, **kwasync)
psycopg2.OperationalError: could not connect to server: Connection timed out
	Is the server running on host "192.168.0.235" and accepting
	TCP/IP connections on port 5432?



Traceback (most recent call last):
  File "/home/pi/Desktop/message.py", line 23, in <module>
    conn = psycopg2.connect(database="performance", user='pi', password='Sox2017!', host='192.168.0.235', port= '5432')
  File "/usr/local/lib/python2.7/dist-packages/psycopg2/__init__.py", line 127, in connect
    conn = _connect(dsn, connection_factory=connection_factory, **kwasync)
psycopg2.OperationalError: could not connect to server: Connection timed out
	Is the server running on host "192.168.0.235" and accepting
	TCP/IP connections on port 5432?



Traceback (most recent call last):
  File "/home/pi/Desktop/message.py", line 23, in <module>
    conn = psycopg2.connect(database="performance", user='pi', password='Sox2017!', host='192.168.0.235', port= '5432')
  File "/usr/local/lib/python2.7/dist-packages/psycopg2/__init__.py", line 127, in connect
    conn = _connect(dsn, connection_factory=connection_factory, **kwasync)
psycopg2.OperationalError: could not connect to server: Connection timed out
	Is the server running on host "192.168.0.235" and accepting
	TCP/IP connections on port 5432?



Traceback (most recent call last):
  File "/home/pi/Desktop/message.py", line 23, in <module>
    conn = psycopg2.connect(database="performance", user='pi', password='Sox2017!', host='192.168.0.235', port= '5432')
  File "/usr/local/lib/python2.7/dist-packages/psycopg2/__init__.py", line 127, in connect
    conn = _connect(dsn, connection_factory=connection_factory, **kwasync)
psycopg2.OperationalError: could not connect to server: Connection timed out
	Is the server running on host "192.168.0.235" and accepting
	TCP/IP connections on port 5432?



Traceback (most recent call last):
  File "/home/pi/Desktop/message.py", line 23, in <module>
    conn = psycopg2.connect(database="performance", user='pi', password='Sox2017!', host='192.168.0.235', port= '5432')
  File "/usr/local/lib/python2.7/dist-packages/psycopg2/__init__.py", line 127, in connect
    conn = _connect(dsn, connection_factory=connection_factory, **kwasync)
psycopg2.OperationalError: could not connect to server: Connection timed out
	Is the server running on host "192.168.0.235" and accepting
	TCP/IP connections on port 5432?



Traceback (most recent call last):
  File "/home/pi/Desktop/message.py", line 23, in <module>
    conn = psycopg2.connect(database="performance", user='pi', password='Sox2017!', host='192.168.0.235', port= '5432')
  File "/usr/local/lib/python2.7/dist-packages/psycopg2/__init__.py", line 127, in connect
    conn = _connect(dsn, connection_factory=connection_factory, **kwasync)
psycopg2.OperationalError: could not connect to server: Network is unreachable
	Is the server running on host "192.168.0.235" and accepting
	TCP/IP connections on port 5432?

                                                                                                                                                                                                                                                                                                                                                                                                                                                                                                                                                                             

Traceback (most recent call last):
  File "/home/pi/Desktop/message.py", line 23, in <module>
    conn = psycopg2.connect(database="performance", user='pi', password='Sox2017!', host='192.168.0.235', port= '5432')
  File "/usr/local/lib/python2.7/dist-packages/psycopg2/__init__.py", line 127, in connect
    conn = _connect(dsn, connection_factory=connection_factory, **kwasync)
psycopg2.OperationalError: could not connect to server: Network is unreachable
	Is the server running on host "192.168.0.235" and accepting
	TCP/IP connections on port 5432?



Traceback (most recent call last):
  File "/home/pi/Desktop/message.py", line 23, in <module>
    conn = psycopg2.connect(database="performance", user='pi', password='Sox2017!', host='192.168.0.235', port= '5432')
  File "/usr/local/lib/python2.7/dist-packages/psycopg2/__init__.py", line 127, in connect
    conn = _connect(dsn, connection_factory=connection_factory, **kwasync)
psycopg2.OperationalError: could not connect to server: Network is unreachable
	Is the server running on host "192.168.0.235" and accepting
	TCP/IP connections on port 5432?



Traceback (most recent call last):
  File "/home/pi/Desktop/message.py", line 23, in <module>
    conn = psycopg2.connect(database="performance", user='pi', password='Sox2017!', host='192.168.0.235', port= '5432')
  File "/usr/local/lib/python2.7/dist-packages/psycopg2/__init__.py", line 127, in connect
    conn = _connect(dsn, connection_factory=connection_factory, **kwasync)
psycopg2.OperationalError: could not connect to server: Network is unreachable
	Is the server running on host "192.168.0.235" and accepting
	TCP/IP connections on port 5432?



Traceback (most recent call last):
  File "/home/pi/Desktop/message.py", line 23, in <module>
    conn = psycopg2.connect(database="performance", user='pi', password='Sox2017!', host='192.168.0.235', port= '5432')
  File "/usr/local/lib/python2.7/dist-packages/psycopg2/__init__.py", line 127, in connect
    conn = _connect(dsn, connection_factory=connection_factory, **kwasync)
psycopg2.OperationalError: could not connect to server: Network is unreachable
	Is the server running on host "192.168.0.235" and accepting
	TCP/IP connections on port 5432?



Traceback (most recent call last):
  File "/home/pi/Desktop/message.py", line 23, in <module>
    conn = psycopg2.connect(database="performance", user='pi', password='Sox2017!', host='192.168.0.235', port= '5432')
  File "/usr/local/lib/python2.7/dist-packages/psycopg2/__init__.py", line 127, in connect
    conn = _connect(dsn, connection_factory=connection_factory, **kwasync)
psycopg2.OperationalError: could not connect to server: Network is unreachable
	Is the server running on host "192.168.0.235" and accepting
	TCP/IP connections on port 5432?



Traceback (most recent call last):
  File "/home/pi/Desktop/message.py", line 23, in <module>
    conn = psycopg2.connect(database="performance", user='pi', password='Sox2017!', host='192.168.0.235', port= '5432')
  File "/usr/local/lib/python2.7/dist-packages/psycopg2/__init__.py", line 127, in connect
    conn = _connect(dsn, connection_factory=connection_factory, **kwasync)
psycopg2.OperationalError: could not connect to server: Network is unreachable
	Is the server running on host "192.168.0.235" and accepting
	TCP/IP connections on port 5432?



Traceback (most recent call last):
  File "/home/pi/Desktop/message.py", line 23, in <module>
    conn = psycopg2.connect(database="performance", user='pi', password='Sox2017!', host='192.168.0.235', port= '5432')
  File "/usr/local/lib/python2.7/dist-packages/psycopg2/__init__.py", line 127, in connect
    conn = _connect(dsn, connection_factory=connection_factory, **kwasync)
psycopg2.OperationalError: could not connect to server: Network is unreachable
	Is the server running on host "192.168.0.235" and accepting
	TCP/IP connections on port 5432?



Traceback (most recent call last):
  File "/home/pi/Desktop/message.py", line 23, in <module>
    conn = psycopg2.connect(database="performance", user='pi', password='Sox2017!', host='192.168.0.235', port= '5432')
  File "/usr/local/lib/python2.7/dist-packages/psycopg2/__init__.py", line 127, in connect
    conn = _connect(dsn, connection_factory=connection_factory, **kwasync)
psycopg2.OperationalError: could not connect to server: Network is unreachable
	Is the server running on host "192.168.0.235" and accepting
	TCP/IP connections on port 5432?



Traceback (most recent call last):
  File "/home/pi/Desktop/message.py", line 23, in <module>
    conn = psycopg2.connect(database="performance", user='pi', password='Sox2017!', host='192.168.0.235', port= '5432')
  File "/usr/local/lib/python2.7/dist-packages/psycopg2/__init__.py", line 127, in connect
    conn = _connect(dsn, connection_factory=connection_factory, **kwasync)
psycopg2.OperationalError: could not connect to server: Network is unreachable
	Is the server running on host "192.168.0.235" and accepting
	TCP/IP connections on port 5432?



Traceback (most recent call last):
  File "/home/pi/Desktop/message.py", line 23, in <module>
    conn = psycopg2.connect(database="performance", user='pi', password='Sox2017!', host='192.168.0.235', port= '5432')
  File "/usr/local/lib/python2.7/dist-packages/psycopg2/__init__.py", line 127, in connect
    conn = _connect(dsn, connection_factory=connection_factory, **kwasync)
psycopg2.OperationalError: could not connect to server: Network is unreachable
	Is the server running on host "192.168.0.235" and accepting
	TCP/IP connections on port 5432?



Traceback (most recent call last):
  File "/home/pi/Desktop/message.py", line 23, in <module>
    conn = psycopg2.connect(database="performance", user='pi', password='Sox2017!', host='192.168.0.235', port= '5432')
  File "/usr/local/lib/python2.7/dist-packages/psycopg2/__init__.py", line 127, in connect
    conn = _connect(dsn, connection_factory=connection_factory, **kwasync)
psycopg2.OperationalError: could not connect to server: Network is unreachable
	Is the server running on host "192.168.0.235" and accepting
	TCP/IP connections on port 5432?



Traceback (most recent call last):
  File "/home/pi/Desktop/message.py", line 23, in <module>
    conn = psycopg2.connect(database="performance", user='pi', password='Sox2017!', host='192.168.0.235', port= '5432')
  File "/usr/local/lib/python2.7/dist-packages/psycopg2/__init__.py", line 127, in connect
    conn = _connect(dsn, connection_factory=connection_factory, **kwasync)
psycopg2.OperationalError: could not connect to server: Network is unreachable
	Is the server running on host "192.168.0.235" and accepting
	TCP/IP connections on port 5432?



Traceback (most recent call last):
  File "/home/pi/Desktop/message.py", line 23, in <module>
    conn = psycopg2.connect(database="performance", user='pi', password='Sox2017!', host='192.168.0.235', port= '5432')
  File "/usr/local/lib/python2.7/dist-packages/psycopg2/__init__.py", line 127, in connect
    conn = _connect(dsn, connection_factory=connection_factory, **kwasync)
psycopg2.OperationalError: could not connect to server: Network is unreachable
	Is the server running on host "192.168.0.235" and accepting
	TCP/IP connections on port 5432?



Traceback (most recent call last):
  File "/home/pi/Desktop/message.py", line 23, in <module>
    conn = psycopg2.connect(database="performance", user='pi', password='Sox2017!', host='192.168.0.235', port= '5432')
  File "/usr/local/lib/python2.7/dist-packages/psycopg2/__init__.py", line 127, in connect
    conn = _connect(dsn, connection_factory=connection_factory, **kwasync)
psycopg2.OperationalError: could not connect to server: Network is unreachable
	Is the server running on host "192.168.0.235" and accepting
	TCP/IP connections on port 5432?



Traceback (most recent call last):
  File "/home/pi/Desktop/message.py", line 23, in <module>
    conn = psycopg2.connect(database="performance", user='pi', password='Sox2017!', host='192.168.0.235', port= '5432')
  File "/usr/local/lib/python2.7/dist-packages/psycopg2/__init__.py", line 127, in connect
    conn = _connect(dsn, connection_factory=connection_factory, **kwasync)
psycopg2.OperationalError: could not connect to server: Network is unreachable
	Is the server running on host "192.168.0.235" and accepting
	TCP/IP connections on port 5432?



Traceback (most recent call last):
  File "/home/pi/Desktop/message.py", line 23, in <module>
    conn = psycopg2.connect(database="performance", user='pi', password='Sox2017!', host='192.168.0.235', port= '5432')
  File "/usr/local/lib/python2.7/dist-packages/psycopg2/__init__.py", line 127, in connect
    conn = _connect(dsn, connection_factory=connection_factory, **kwasync)
psycopg2.OperationalError: could not connect to server: Network is unreachable
	Is the server running on host "192.168.0.235" and accepting
	TCP/IP connections on port 5432?



Traceback (most recent call last):
  File "/home/pi/Desktop/message.py", line 23, in <module>
    conn = psycopg2.connect(database="performance", user='pi', password='Sox2017!', host='192.168.0.235', port= '5432')
  File "/usr/local/lib/python2.7/dist-packages/psycopg2/__init__.py", line 127, in connect
    conn = _connect(dsn, connection_factory=connection_factory, **kwasync)
psycopg2.OperationalError: could not connect to server: Network is unreachable
	Is the server running on host "192.168.0.235" and accepting
	TCP/IP connections on port 5432?



Traceback (most recent call last):
  File "/home/pi/Desktop/message.py", line 23, in <module>
    conn = psycopg2.connect(database="performance", user='pi', password='Sox2017!', host='192.168.0.235', port= '5432')
  File "/usr/local/lib/python2.7/dist-packages/psycopg2/__init__.py", line 127, in connect
    conn = _connect(dsn, connection_factory=connection_factory, **kwasync)
psycopg2.OperationalError: could not connect to server: Network is unreachable
	Is the server running on host "192.168.0.235" and accepting
	TCP/IP connections on port 5432?



Traceback (most recent call last):
  File "/home/pi/Desktop/message.py", line 23, in <module>
    conn = psycopg2.connect(database="performance", user='pi', password='Sox2017!', host='192.168.0.235', port= '5432')
  File "/usr/local/lib/python2.7/dist-packages/psycopg2/__init__.py", line 127, in connect
    conn = _connect(dsn, connection_factory=connection_factory, **kwasync)
psycopg2.OperationalError: could not connect to server: Network is unreachable
	Is the server running on host "192.168.0.235" and accepting
	TCP/IP connections on port 5432?



Traceback (most recent call last):
  File "/home/pi/Desktop/message.py", line 23, in <module>
    conn = psycopg2.connect(database="performance", user='pi', password='Sox2017!', host='192.168.0.235', port= '5432')
  File "/usr/local/lib/python2.7/dist-packages/psycopg2/__init__.py", line 127, in connect
    conn = _connect(dsn, connection_factory=connection_factory, **kwasync)
psycopg2.OperationalError: could not connect to server: Network is unreachable
	Is the server running on host "192.168.0.235" and accepting
	TCP/IP connections on port 5432?



Traceback (most recent call last):
  File "/home/pi/Desktop/message.py", line 23, in <module>
    conn = psycopg2.connect(database="performance", user='pi', password='Sox2017!', host='192.168.0.235', port= '5432')
  File "/usr/local/lib/python2.7/dist-packages/psycopg2/__init__.py", line 127, in connect
    conn = _connect(dsn, connection_factory=connection_factory, **kwasync)
psycopg2.OperationalError: could not connect to server: Network is unreachable
	Is the server running on host "192.168.0.235" and accepting
	TCP/IP connections on port 5432?



Traceback (most recent call last):
  File "/home/pi/Desktop/message.py", line 23, in <module>
    conn = psycopg2.connect(database="performance", user='pi', password='Sox2017!', host='192.168.0.235', port= '5432')
  File "/usr/local/lib/python2.7/dist-packages/psycopg2/__init__.py", line 127, in connect
    conn = _connect(dsn, connection_factory=connection_factory, **kwasync)
psycopg2.OperationalError: could not connect to server: Network is unreachable
	Is the server running on host "192.168.0.235" and accepting
	TCP/IP connections on port 5432?



Traceback (most recent call last):
  File "/home/pi/Desktop/message.py", line 23, in <module>
    conn = psycopg2.connect(database="performance", user='pi', password='Sox2017!', host='192.168.0.235', port= '5432')
  File "/usr/local/lib/python2.7/dist-packages/psycopg2/__init__.py", line 127, in connect
    conn = _connect(dsn, connection_factory=connection_factory, **kwasync)
psycopg2.OperationalError: could not connect to server: Network is unreachable
	Is the server running on host "192.168.0.235" and accepting
	TCP/IP connections on port 5432?



Traceback (most recent call last):
  File "/home/pi/Desktop/message.py", line 23, in <module>
    conn = psycopg2.connect(database="performance", user='pi', password='Sox2017!', host='192.168.0.235', port= '5432')
  File "/usr/local/lib/python2.7/dist-packages/psycopg2/__init__.py", line 127, in connect
    conn = _connect(dsn, connection_factory=connection_factory, **kwasync)
psycopg2.OperationalError: could not connect to server: Network is unreachable
	Is the server running on host "192.168.0.235" and accepting
	TCP/IP connections on port 5432?



Traceback (most recent call last):
  File "/home/pi/Desktop/message.py", line 23, in <module>
    conn = psycopg2.connect(database="performance", user='pi', password='Sox2017!', host='192.168.0.235', port= '5432')
  File "/usr/local/lib/python2.7/dist-packages/psycopg2/__init__.py", line 127, in connect
    conn = _connect(dsn, connection_factory=connection_factory, **kwasync)
psycopg2.OperationalError: could not connect to server: Network is unreachable
	Is the server running on host "192.168.0.235" and accepting
	TCP/IP connections on port 5432?



Traceback (most recent call last):
  File "/home/pi/Desktop/message.py", line 23, in <module>
    conn = psycopg2.connect(database="performance", user='pi', password='Sox2017!', host='192.168.0.235', port= '5432')
  File "/usr/local/lib/python2.7/dist-packages/psycopg2/__init__.py", line 127, in connect
    conn = _connect(dsn, connection_factory=connection_factory, **kwasync)
psycopg2.OperationalError: could not connect to server: Network is unreachable
	Is the server running on host "192.168.0.235" and accepting
	TCP/IP connections on port 5432?



Traceback (most recent call last):
  File "/home/pi/Desktop/message.py", line 23, in <module>
    conn = psycopg2.connect(database="performance", user='pi', password='Sox2017!', host='192.168.0.235', port= '5432')
  File "/usr/local/lib/python2.7/dist-packages/psycopg2/__init__.py", line 127, in connect
    conn = _connect(dsn, connection_factory=connection_factory, **kwasync)
psycopg2.OperationalError: could not connect to server: Network is unreachable
	Is the server running on host "192.168.0.235" and accepting
	TCP/IP connections on port 5432?



Traceback (most recent call last):
  File "/home/pi/Desktop/message.py", line 23, in <module>
    conn = psycopg2.connect(database="performance", user='pi', password='Sox2017!', host='192.168.0.235', port= '5432')
  File "/usr/local/lib/python2.7/dist-packages/psycopg2/__init__.py", line 127, in connect
    conn = _connect(dsn, connection_factory=connection_factory, **kwasync)
psycopg2.OperationalError: could not connect to server: Network is unreachable
	Is the server running on host "192.168.0.235" and accepting
	TCP/IP connections on port 5432?



Traceback (most recent call last):
  File "/home/pi/Desktop/message.py", line 23, in <module>
    conn = psycopg2.connect(database="performance", user='pi', password='Sox2017!', host='192.168.0.235', port= '5432')
  File "/usr/local/lib/python2.7/dist-packages/psycopg2/__init__.py", line 127, in connect
    conn = _connect(dsn, connection_factory=connection_factory, **kwasync)
psycopg2.OperationalError: could not connect to server: Network is unreachable
	Is the server running on host "192.168.0.235" and accepting
	TCP/IP connections on port 5432?



Traceback (most recent call last):
  File "/home/pi/Desktop/message.py", line 23, in <module>
    conn = psycopg2.connect(database="performance", user='pi', password='Sox2017!', host='192.168.0.235', port= '5432')
  File "/usr/local/lib/python2.7/dist-packages/psycopg2/__init__.py", line 127, in connect
    conn = _connect(dsn, connection_factory=connection_factory, **kwasync)
psycopg2.OperationalError: could not connect to server: Network is unreachable
	Is the server running on host "192.168.0.235" and accepting
	TCP/IP connections on port 5432?



Traceback (most recent call last):
  File "/home/pi/Desktop/message.py", line 23, in <module>
    conn = psycopg2.connect(database="performance", user='pi', password='Sox2017!', host='192.168.0.235', port= '5432')
  File "/usr/local/lib/python2.7/dist-packages/psycopg2/__init__.py", line 127, in connect
    conn = _connect(dsn, connection_factory=connection_factory, **kwasync)
psycopg2.OperationalError: could not connect to server: Network is unreachable
	Is the server running on host "192.168.0.235" and accepting
	TCP/IP connections on port 5432?



Traceback (most recent call last):
  File "/home/pi/Desktop/message.py", line 23, in <module>
    conn = psycopg2.connect(database="performance", user='pi', password='Sox2017!', host='192.168.0.235', port= '5432')
  File "/usr/local/lib/python2.7/dist-packages/psycopg2/__init__.py", line 127, in connect
    conn = _connect(dsn, connection_factory=connection_factory, **kwasync)
psycopg2.OperationalError: could not connect to server: Network is unreachable
	Is the server running on host "192.168.0.235" and accepting
	TCP/IP connections on port 5432?



Traceback (most recent call last):
  File "/home/pi/Desktop/message.py", line 23, in <module>
    conn = psycopg2.connect(database="performance", user='pi', password='Sox2017!', host='192.168.0.235', port= '5432')
  File "/usr/local/lib/python2.7/dist-packages/psycopg2/__init__.py", line 127, in connect
    conn = _connect(dsn, connection_factory=connection_factory, **kwasync)
psycopg2.OperationalError: could not connect to server: Network is unreachable
	Is the server running on host "192.168.0.235" and accepting
	TCP/IP connections on port 5432?



Traceback (most recent call last):
  File "/home/pi/Desktop/message.py", line 23, in <module>
    conn = psycopg2.connect(database="performance", user='pi', password='Sox2017!', host='192.168.0.235', port= '5432')
  File "/usr/local/lib/python2.7/dist-packages/psycopg2/__init__.py", line 127, in connect
    conn = _connect(dsn, connection_factory=connection_factory, **kwasync)
psycopg2.OperationalError: could not connect to server: Network is unreachable
	Is the server running on host "192.168.0.235" and accepting
	TCP/IP connections on port 5432?



Traceback (most recent call last):
  File "/home/pi/Desktop/message.py", line 23, in <module>
    conn = psycopg2.connect(database="performance", user='pi', password='Sox2017!', host='192.168.0.235', port= '5432')
  File "/usr/local/lib/python2.7/dist-packages/psycopg2/__init__.py", line 127, in connect
    conn = _connect(dsn, connection_factory=connection_factory, **kwasync)
psycopg2.OperationalError: could not connect to server: Network is unreachable
	Is the server running on host "192.168.0.235" and accepting
	TCP/IP connections on port 5432?



Traceback (most recent call last):
  File "/home/pi/Desktop/message.py", line 23, in <module>
    conn = psycopg2.connect(database="performance", user='pi', password='Sox2017!', host='192.168.0.235', port= '5432')
  File "/usr/local/lib/python2.7/dist-packages/psycopg2/__init__.py", line 127, in connect
    conn = _connect(dsn, connection_factory=connection_factory, **kwasync)
psycopg2.OperationalError: could not connect to server: Network is unreachable
	Is the server running on host "192.168.0.235" and accepting
	TCP/IP connections on port 5432?



Traceback (most recent call last):
  File "/home/pi/Desktop/message.py", line 23, in <module>
    conn = psycopg2.connect(database="performance", user='pi', password='Sox2017!', host='192.168.0.235', port= '5432')
  File "/usr/local/lib/python2.7/dist-packages/psycopg2/__init__.py", line 127, in connect
    conn = _connect(dsn, connection_factory=connection_factory, **kwasync)
psycopg2.OperationalError: could not connect to server: Network is unreachable
	Is the server running on host "192.168.0.235" and accepting
	TCP/IP connections on port 5432?



Traceback (most recent call last):
  File "/home/pi/Desktop/message.py", line 23, in <module>
    conn = psycopg2.connect(database="performance", user='pi', password='Sox2017!', host='192.168.0.235', port= '5432')
  File "/usr/local/lib/python2.7/dist-packages/psycopg2/__init__.py", line 127, in connect
    conn = _connect(dsn, connection_factory=connection_factory, **kwasync)
psycopg2.OperationalError: could not connect to server: Network is unreachable
	Is the server running on host "192.168.0.235" and accepting
	TCP/IP connections on port 5432?



Traceback (most recent call last):
  File "/home/pi/Desktop/message.py", line 23, in <module>
    conn = psycopg2.connect(database="performance", user='pi', password='Sox2017!', host='192.168.0.235', port= '5432')
  File "/usr/local/lib/python2.7/dist-packages/psycopg2/__init__.py", line 127, in connect
    conn = _connect(dsn, connection_factory=connection_factory, **kwasync)
psycopg2.OperationalError: could not connect to server: Network is unreachable
	Is the server running on host "192.168.0.235" and accepting
	TCP/IP connections on port 5432?



Traceback (most recent call last):
  File "/home/pi/Desktop/message.py", line 23, in <module>
    conn = psycopg2.connect(database="performance", user='pi', password='Sox2017!', host='192.168.0.235', port= '5432')
  File "/usr/local/lib/python2.7/dist-packages/psycopg2/__init__.py", line 127, in connect
    conn = _connect(dsn, connection_factory=connection_factory, **kwasync)
psycopg2.OperationalError: could not connect to server: Network is unreachable
	Is the server running on host "192.168.0.235" and accepting
	TCP/IP connections on port 5432?



Traceback (most recent call last):
  File "/home/pi/Desktop/message.py", line 23, in <module>
    conn = psycopg2.connect(database="performance", user='pi', password='Sox2017!', host='192.168.0.235', port= '5432')
  File "/usr/local/lib/python2.7/dist-packages/psycopg2/__init__.py", line 127, in connect
    conn = _connect(dsn, connection_factory=connection_factory, **kwasync)
psycopg2.OperationalError: could not connect to server: Network is unreachable
	Is the server running on host "192.168.0.235" and accepting
	TCP/IP connections on port 5432?



Traceback (most recent call last):
  File "/home/pi/Desktop/message.py", line 23, in <module>
    conn = psycopg2.connect(database="performance", user='pi', password='Sox2017!', host='192.168.0.235', port= '5432')
  File "/usr/local/lib/python2.7/dist-packages/psycopg2/__init__.py", line 127, in connect
    conn = _connect(dsn, connection_factory=connection_factory, **kwasync)
psycopg2.OperationalError: could not connect to server: Connection timed out
	Is the server running on host "192.168.0.235" and accepting
	TCP/IP connections on port 5432?



Traceback (most recent call last):
  File "/home/pi/Desktop/message.py", line 23, in <module>
    conn = psycopg2.connect(database="performance", user='pi', password='Sox2017!', host='192.168.0.235', port= '5432')
  File "/usr/local/lib/python2.7/dist-packages/psycopg2/__init__.py", line 127, in connect
    conn = _connect(dsn, connection_factory=connection_factory, **kwasync)
psycopg2.OperationalError: could not connect to server: Connection timed out
	Is the server running on host "192.168.0.235" and accepting
	TCP/IP connections on port 5432?



Traceback (most recent call last):
  File "/home/pi/Desktop/message.py", line 23, in <module>
    conn = psycopg2.connect(database="performance", user='pi', password='Sox2017!', host='192.168.0.235', port= '5432')
  File "/usr/local/lib/python2.7/dist-packages/psycopg2/__init__.py", line 127, in connect
    conn = _connect(dsn, connection_factory=connection_factory, **kwasync)
psycopg2.OperationalError: could not connect to server: Connection timed out
	Is the server running on host "192.168.0.235" and accepting
	TCP/IP connections on port 5432?



Traceback (most recent call last):
  File "/home/pi/Desktop/message.py", line 23, in <module>
    conn = psycopg2.connect(database="performance", user='pi', password='Sox2017!', host='192.168.0.235', port= '5432')
  File "/usr/local/lib/python2.7/dist-packages/psycopg2/__init__.py", line 127, in connect
    conn = _connect(dsn, connection_factory=connection_factory, **kwasync)
psycopg2.OperationalError: could not connect to server: Connection timed out
	Is the server running on host "192.168.0.235" and accepting
	TCP/IP connections on port 5432?



Traceback (most recent call last):
  File "/home/pi/Desktop/message.py", line 23, in <module>
    conn = psycopg2.connect(database="performance", user='pi', password='Sox2017!', host='192.168.0.235', port= '5432')
  File "/usr/local/lib/python2.7/dist-packages/psycopg2/__init__.py", line 127, in connect
    conn = _connect(dsn, connection_factory=connection_factory, **kwasync)
psycopg2.OperationalError: could not connect to server: Connection timed out
	Is the server running on host "192.168.0.235" and accepting
	TCP/IP connections on port 5432?



Traceback (most recent call last):
  File "/home/pi/Desktop/message.py", line 23, in <module>
    conn = psycopg2.connect(database="performance", user='pi', password='Sox2017!', host='192.168.0.235', port= '5432')
  File "/usr/local/lib/python2.7/dist-packages/psycopg2/__init__.py", line 127, in connect
    conn = _connect(dsn, connection_factory=connection_factory, **kwasync)
psycopg2.OperationalError: could not connect to server: No route to host
	Is the server running on host "192.168.0.235" and accepting
	TCP/IP connections on port 5432?

